Workbook

Sheet Dash
A1: Signal | C1: Value | E1: Days | K1: Ticker Description | L1: Last %Change | M1: Ticker | N1: TOS Ticker | O1: HE OL | P1: TrTn OL | Q1: MQ | R1: QQ | S1: Last | T1: A_TrendValue | U1: A_TradeValue | V1: %BRR | X1: Low | Y1: High | Z1: Invest | AB1: Main Date | AC1: Data Refresh Dates | AF1: Data Dates | AG1: Imported Date | AH1: Incl Date Range | AJ1: Investments | AK1: Amount | AM1: Desc | AN1: Desc Date | AO1: TD Import Date Time | AP1: TL Import Date | AQ1: TW Import Date | AR1: TD Import Date | AS1: TO Import Date
A2: Holiday? | C2: =_xlfn.MINIFS(Data!$O:$O,Data!$O:$O,">" & Dash!$AB$2) -> 46167 | E2: =_xlfn.DAYS(C2,Dash!$AB$2) -> 25 | K2: VIX | L2: =_xlfn.XLOOKUP(M2,MA!C:C,MA!H:H,"") | M2: ^VIX | N2: VIX | O2: =_xlfn.XLOOKUP(M2,MA!C:C,MA!VP:VP,"") | P2: =_xlfn.XLOOKUP(M2,MA!C:C,MA!VQ:VQ,"") | S2: =_xlfn.XLOOKUP(M2,MA!C:C,MA!D:D,"") | T2: =_xlfn.XLOOKUP(M2,MA!C:C,MA!K:K,"") | U2: =_xlfn.XLOOKUP(M2,MA!C:C,MA!L:L,"") | V2: =(T2-S2)*100/(T2-U2) -> #VALUE! | X2: 19 | Y2: 30 | Z2: =IF(S2<=X2,"Y",IF(S2>=Y2,"N","W")) -> N | AB2: 46142 | AC2: Today | AF2: RR | AG2: =MAX(RR!D:D) -> 46141 | AJ2: Total | AK2: 200000 | AM2: Today | AN2: =Dash!$AB$2 -> 46142 | AO2: =_xlfn.MAXIFS(TD!B:B,TD!B:B,"<=" & AN2) -> 46141.688 | AP2: =_xlfn.MAXIFS(TL!B:B,TL!B:B,"<=" & AN2) -> 46141.688 | AQ2: =_xlfn.MAXIFS(TW!B:B,TW!B:B,"<=" & AN2) -> 46141.688 | AR2: =INT(AO2) -> 46141 | AS2: =_xlfn.MAXIFS(TO!B:B,TO!B:B,"<=" & AN2) -> 46139.688
A3: Incl Eco Days | C3: =$AB$2+7 -> 46149 | E3: =_xlfn.DAYS(C3,Dash!$AB$2) -> 7 | K3: CBOE VIX VOLATILITY INDEX | L3: =_xlfn.XLOOKUP(M3,MA!C:C,MA!H:H,"") | M3: ^VVIX | N3: VVIX | O3: =_xlfn.XLOOKUP(M3,MA!C:C,MA!VP:VP,"") | P3: =_xlfn.XLOOKUP(M3,MA!C:C,MA!VQ:VQ,"") | S3: =_xlfn.XLOOKUP(M3,MA!C:C,MA!D:D,"") | T3: =_xlfn.XLOOKUP(M3,MA!C:C,MA!K:K,"") | U3: =_xlfn.XLOOKUP(M3,MA!C:C,MA!L:L,"") | V3: =(T3-S3)*100/(T3-U3) -> #VALUE! | X3: 100 | Y3: 150 | Z3: =IF(S3<=X3,"Y",IF(S3>=Y3,"N","W")) -> N | AC3: Overwrite Main date | AF3: CAll | AG3: =MAX(call!C:C) -> 46141 | AH3: =EDATE($AB$2, -1) -> 46111 | AJ3: PS | AK3: 400000 | AM3: Day Ago | AN3: =WORKDAY(AN2,-1) -> 46141 | AO3: =_xlfn.MAXIFS(TD!B:B,TD!B:B,"<=" & AN3) -> 0 | AP3: =_xlfn.MAXIFS(TL!B:B,TL!B:B,"<=" & AN3) -> 0 | AQ3: =_xlfn.MAXIFS(TW!B:B,TW!B:B,"<=" & AN3) -> 0 | AR3: =INT(AO3) -> 0 | AS3: =_xlfn.MAXIFS(TO!B:B,TO!B:B,"<=" & AN3) -> 46139.688
A4: Econ.Ind 1 | B4: 1 | C4: {=INDEX(_xlfn._xlws.SORT(_xlfn._xlws.FILTER(Data!$C:$H, (Data!$L:$L="Y"),""),3),B4)} -> Fed Blackout Period | D4: 46130 | E4: -12 | F4: BULLISH | G4: 46130 | H4: 46189 | K4: CBOE RUSSell 2000 VOLATILITY IN | L4: =_xlfn.XLOOKUP(M4,MA!C:C,MA!H:H,"") | M4: ^RVX | N4: RVX | O4: =_xlfn.XLOOKUP(M4,MA!C:C,MA!VP:VP,"") | P4: =_xlfn.XLOOKUP(M4,MA!C:C,MA!VQ:VQ,"") | S4: =_xlfn.XLOOKUP(M4,MA!C:C,MA!D:D,"") | T4: =_xlfn.XLOOKUP(M4,MA!C:C,MA!K:K,"") | U4: =_xlfn.XLOOKUP(M4,MA!C:C,MA!L:L,"") | V4: =(T4-S4)*100/(T4-U4) -> #VALUE! | X4: 22 | Y4: 40 | Z4: =IF(S4<=X4,"Y",IF(S4>=Y4,"N","W")) -> N | AB4: =IF(AB18>=AB14,"Y","N") -> Y | AC4: After close TOS Export used? | AF4: ETF | AG4: =MAX(etf!C:C) -> 46019 | AH4: =EDATE($AB$2, -1) -> 46111 | AJ4: SSS | AK4: 100000 | AM4: 3 Days Ago | AN4: =WORKDAY(AN2,-3) -> 46139 | AO4: =_xlfn.MAXIFS(TD!B:B,TD!B:B,"<=" & AN4) -> 0 | AP4: =_xlfn.MAXIFS(TL!B:B,TL!B:B,"<=" & AN4) -> 0 | AQ4: =_xlfn.MAXIFS(TW!B:B,TW!B:B,"<=" & AN4) -> 0 | AR4: =INT(AO4) -> 0 | AS4: =_xlfn.MAXIFS(TO!B:B,TO!B:B,"<=" & AN4) -> 0
A5: Econ.Ind 2 | B5: 2 | C5: {=INDEX(_xlfn._xlws.SORT(_xlfn._xlws.FILTER(Data!$C:$H, (Data!$L:$L="Y"),""),3),B5)} -> Month end marking - 3 days before - Buy CAlls | D5: 46142 | E5: -3 | F5: BULLISH | G5: 46139 | H5: 46142 | K5: Nasdaq-100 vol Index (out $ opts) | L5: =_xlfn.XLOOKUP(M5,MA!C:C,MA!H:H,"") | M5: ^VXN | N5: VXN:CGI | O5: =_xlfn.XLOOKUP(M5,MA!C:C,MA!VP:VP,"") | P5: =_xlfn.XLOOKUP(M5,MA!C:C,MA!VQ:VQ,"") | S5: =_xlfn.XLOOKUP(M5,MA!C:C,MA!D:D,"") | T5: =_xlfn.XLOOKUP(M5,MA!C:C,MA!K:K,"") | U5: =_xlfn.XLOOKUP(M5,MA!C:C,MA!L:L,"") | V5: =(T5-S5)*100/(T5-U5) -> #VALUE! | X5: 22 | Y5: 32 | Z5: =IF(S5<=X5,"Y",IF(S5>=Y5,"N","W")) -> N | AB5: =IF(AB22>=AB14,"Y","N") -> Y | AC5: After close Y Export used? | AF5: PS | AG5: =MAX(psRk!A:A) -> 46146 | AJ5: My | AK5: 20000 | AM5: Wk Ago | AN5: =WORKDAY(AN2,-5) -> 46135 | AO5: =_xlfn.MAXIFS(TD!B:B,TD!B:B,"<=" & AN5) -> 0 | AP5: =_xlfn.MAXIFS(TL!B:B,TL!B:B,"<=" & AN5) -> 0 | AQ5: =_xlfn.MAXIFS(TW!B:B,TW!B:B,"<=" & AN5) -> 0 | AR5: =INT(AO5) -> 0 | AS5: =_xlfn.MAXIFS(TO!B:B,TO!B:B,"<=" & AN5) -> 0
A6: Econ.Ind 3 | B6: 3 | C6: {=INDEX(_xlfn._xlws.SORT(_xlfn._xlws.FILTER(Data!$C:$H, (Data!$L:$L="Y"),""),3),B6)} -> Month end marking - 3 days after - Buy Puts (Crypto) | D6: 46142 | E6: -2 | F6: BEARISH | G6: 46140 | H6: 46147 | K6: CBOE Gold Volatitity Index | L6: =_xlfn.XLOOKUP(M6,MA!C:C,MA!H:H,"") | M6: ^GVZ | N6: GVZ:CGI | O6: =_xlfn.XLOOKUP(M6,MA!C:C,MA!VP:VP,"") | P6: =_xlfn.XLOOKUP(M6,MA!C:C,MA!VQ:VQ,"") | S6: =_xlfn.XLOOKUP(M6,MA!C:C,MA!D:D,"") | T6: =_xlfn.XLOOKUP(M6,MA!C:C,MA!K:K,"") | U6: =_xlfn.XLOOKUP(M6,MA!C:C,MA!L:L,"") | V6: =(T6-S6)*100/(T6-U6) -> #VALUE! | X6: 26 | Y6: 32 | Z6: =IF(S6<=X6,"Y",IF(S6>=Y6,"N","W")) -> N | AB6: Y | AC6: Use latest Y export | AF6: SSS | AG6: =MAX(ssH!B:B) -> 46140 | AH6: =EDATE($AB$2, -1) -> 46111 | AM6: 3 Wks Ago | AN6: =WORKDAY(AN2,-5*3) -> 46121 | AO6: =_xlfn.MAXIFS(TD!B:B,TD!B:B,"<=" & AN6) -> 0 | AP6: =_xlfn.MAXIFS(TL!B:B,TL!B:B,"<=" & AN6) -> 0 | AQ6: =_xlfn.MAXIFS(TW!B:B,TW!B:B,"<=" & AN6) -> 0 | AR6: =INT(AO6) -> 0 | AS6: =_xlfn.MAXIFS(TO!B:B,TO!B:B,"<=" & AN6) -> 0
A7: Econ.Ind 4 | B7: 4 | C7: {=INDEX(_xlfn._xlws.SORT(_xlfn._xlws.FILTER(Data!$C:$H, (Data!$L:$L="Y"),""),3),B7)} -> Personal Consumption Expenditures - PCE | D7: 46142 | E7: -1 | F7: 0 | G7: 46141 | H7: 46141 | K7: CBOE Crude Oil Volatility Index | L7: =_xlfn.XLOOKUP(M7,MA!C:C,MA!H:H,"") | M7: ^OVX | N7: OVX:CGI | O7: =_xlfn.XLOOKUP(M7,MA!C:C,MA!VP:VP,"") | P7: =_xlfn.XLOOKUP(M7,MA!C:C,MA!VQ:VQ,"") | S7: =_xlfn.XLOOKUP(M7,MA!C:C,MA!D:D,"") | T7: =_xlfn.XLOOKUP(M7,MA!C:C,MA!K:K,"") | U7: =_xlfn.XLOOKUP(M7,MA!C:C,MA!L:L,"") | V7: =(T7-S7)*100/(T7-U7) -> #VALUE! | X7: 30 | Y7: 50 | Z7: =IF(S7<=X7,"Y",IF(S7>=Y7,"N","W")) -> N | AB7: N | AC7: Use Previous Close Date | AF7: II | AH7: =EDATE($AB$2, -1) -> 46111 | AM7: Month Ago | AN7: =WORKDAY(AN2,-5*4) -> 46114 | AO7: =_xlfn.MAXIFS(TD!B:B,TD!B:B,"<=" & AN7) -> 0 | AP7: =_xlfn.MAXIFS(TL!B:B,TL!B:B,"<=" & AN7) -> 0 | AQ7: =_xlfn.MAXIFS(TW!B:B,TW!B:B,"<=" & AN7) -> 0 | AR7: =INT(AO7) -> 0 | AS7: =_xlfn.MAXIFS(TO!B:B,TO!B:B,"<=" & AN7) -> 0
A8: Econ.Ind 5 | B8: 5 | C8: {=INDEX(_xlfn._xlws.SORT(_xlfn._xlws.FILTER(Data!$C:$H, (Data!$L:$L="Y"),""),3),B8)} -> Gross domestic product - GDP | D8: 46142 | E8: -1 | F8: 0 | G8: 46141 | H8: 46141 | K8: ICE BofAML MOVE Index | L8: =_xlfn.XLOOKUP(M8,MA!C:C,MA!H:H,"") | M8: ^MOVE | N8: MOVE:GIF | O8: =_xlfn.XLOOKUP(M8,MA!C:C,MA!VP:VP,"") | P8: =_xlfn.XLOOKUP(M8,MA!C:C,MA!VQ:VQ,"") | S8: =_xlfn.XLOOKUP(M8,MA!C:C,MA!D:D,"") | T8: =_xlfn.XLOOKUP(M8,MA!C:C,MA!K:K,"") | U8: =_xlfn.XLOOKUP(M8,MA!C:C,MA!L:L,"") | V8: =(T8-S8)*100/(T8-U8) -> #VALUE! | X8: 100 | Y8: 120 | Z8: =IF(S8<=X8,"Y",IF(S8>=Y8,"N","W")) -> N | AB8: 46141 | AC8: Overwrite Market Close Date | AM8: 2 Month Ago | AN8: =WORKDAY(AN2,-5*4*2) -> 46086 | AO8: =_xlfn.MAXIFS(TD!B:B,TD!B:B,"<=" & AN8) -> 0 | AP8: =_xlfn.MAXIFS(TL!B:B,TL!B:B,"<=" & AN8) -> 0 | AQ8: =_xlfn.MAXIFS(TW!B:B,TW!B:B,"<=" & AN8) -> 0 | AR8: =INT(AO8) -> 0 | AS8: =_xlfn.MAXIFS(TO!B:B,TO!B:B,"<=" & AN8) -> 0
A9: Econ.Ind 6 | B9: 6 | C9: {=INDEX(_xlfn._xlws.SORT(_xlfn._xlws.FILTER(Data!$C:$H, (Data!$L:$L="Y"),""),3),B9)} -> Pending Home Sales | D9: 46142 | E9: -1 | F9: 0 | G9: 46141 | H9: 46141 | K9: DJIA VOLATILITY | L9: =_xlfn.XLOOKUP(M9,MA!C:C,MA!H:H,"") | M9: ^VXD | N9: VXD | O9: =_xlfn.XLOOKUP(M9,MA!C:C,MA!VP:VP,"") | P9: =_xlfn.XLOOKUP(M9,MA!C:C,MA!VQ:VQ,"") | S9: =_xlfn.XLOOKUP(M9,MA!C:C,MA!D:D,"") | T9: =_xlfn.XLOOKUP(M9,MA!C:C,MA!K:K,"") | U9: =_xlfn.XLOOKUP(M9,MA!C:C,MA!L:L,"") | V9: =(T9-S9)*100/(T9-U9) -> #VALUE! | X9: 20 | Y9: 30 | Z9: =IF(S9<=X9,"Y",IF(S9>=Y9,"N","W")) -> N | AB9: =IF(AND(WORKDAY(Dash!$AB$2-1,1,Data!$O$2:$O$31)=Dash!$AB$2, OR(Dash!$AB$2<TODAY(),HOUR(NOW())>=16)), Dash!$AB$2, WORKDAY(Dash!$AB$2,-1,Data!$O$2:$O$31)) -> 46142 | AC9: Calculated Market Close Date
A10: Econ.Ind 7 | B10: 7 | C10: {=INDEX(_xlfn._xlws.SORT(_xlfn._xlws.FILTER(Data!$C:$H, (Data!$L:$L="Y"),""),3),B10)} -> Nonfarm payrolls | D10: 46143 | E10: 0 | F10: BEARISH | G10: 46142 | H10: 46142 | O10: =_xlfn.XLOOKUP(M10,MA!C:C,MA!VP:VP,"") -> 0 | P10: =_xlfn.XLOOKUP(M10,MA!C:C,MA!VQ:VQ,"") -> 0 | AB10: =WORKDAY(AB9,-1,Data!$O$2:$O$31) -> 46141 | AC10: Prev Close Date
A11: Econ.Ind 8 | B11: 8 | C11: {=INDEX(_xlfn._xlws.SORT(_xlfn._xlws.FILTER(Data!$C:$H, (Data!$L:$L="Y"),""),3),B11)} -> ISM Mfg | D11: 46145 | E11: 1 | F11: 0 | G11: 46143 | H11: 46143 | K11: S&P500 | L11: =_xlfn.XLOOKUP(M11,MA!C:C,MA!H:H,"") | M11: ^SPX | N11: SPX | O11: =_xlfn.XLOOKUP(M11,MA!C:C,MA!VP:VP,"") | P11: =_xlfn.XLOOKUP(M11,MA!C:C,MA!VQ:VQ,"") | Q11: =_xlfn.XLOOKUP(M11,MA!C:C,MA!IG:IG,"") | R11: =_xlfn.XLOOKUP(M11,MA!C:C,MA!IS:IS,"") | S11: =_xlfn.XLOOKUP(M11,MA!C:C,MA!D:D,"") | T11: =_xlfn.XLOOKUP(M11,MA!C:C,MA!K:K,"") | U11: =_xlfn.XLOOKUP(M11,MA!C:C,MA!L:L,"") | V11: =(T11-S11)*100/(T11-U11) -> #VALUE! | Z11: {=_xlfn.IFS(AND(O11>0,P11>=0),"Y",AND(O11<0,P11<=0),"N",AND(O11>0),"W",AND(O11=0,P11>0),"W",TRUE,"")} -> Y | AB11: =AB10 + TIME(16,0,0) -> 46141.667 | AC11: Prev Close End Date and Time
A12: Econ.Ind 9 | B12: 9 | C12: {=INDEX(_xlfn._xlws.SORT(_xlfn._xlws.FILTER(Data!$C:$H, (Data!$L:$L="Y"),""),3),B12)} -> ISM Svcs | D12: 46146 | E12: 1 | F12: 0 | G12: 46143 | H12: 46143 | K12: Nasdaq | L12: =_xlfn.XLOOKUP(M12,MA!C:C,MA!H:H,"") | M12: ^IXIC | N12: $COMP | O12: =_xlfn.XLOOKUP(M12,MA!C:C,MA!VP:VP,"") | P12: =_xlfn.XLOOKUP(M12,MA!C:C,MA!VQ:VQ,"") | Q12: =_xlfn.XLOOKUP(M12,MA!C:C,MA!IG:IG,"") | R12: =_xlfn.XLOOKUP(M12,MA!C:C,MA!IS:IS,"") | S12: =_xlfn.XLOOKUP(M12,MA!C:C,MA!D:D,"") | T12: =_xlfn.XLOOKUP(M12,MA!C:C,MA!K:K,"") | U12: =_xlfn.XLOOKUP(M12,MA!C:C,MA!L:L,"") | V12: =(T12-S12)*100/(T12-U12) -> #VALUE! | Z12: {=_xlfn.IFS(AND(O12>0,P12>=0),"Y",AND(O12<0,P12<=0),"N",AND(O12>0),"W",AND(O12=0,P12>0),"W",TRUE,"")} -> Y | AB12: =IF($AB$8<>"",$AB$8,IF(AB7="N",AB9,AB10)) -> 46141 | AC12: Using Date as Market Close
A13: Econ.Ind 10 | B13: 10 | C13: {=INDEX(_xlfn._xlws.SORT(_xlfn._xlws.FILTER(Data!$C:$H, (Data!$L:$L="Y"),""),3),B13)} -> Monthly options exp - 2 weeks before (Bullish) | D13: 46157 | E13: 1 | F13: BULLISH | G13: 46143 | H13: 46157 | K13: RusSell 2000 | L13: =_xlfn.XLOOKUP(M13,MA!C:C,MA!H:H,"") | M13: ^RUT | N13: RUT | O13: =_xlfn.XLOOKUP(M13,MA!C:C,MA!VP:VP,"") | P13: =_xlfn.XLOOKUP(M13,MA!C:C,MA!VQ:VQ,"") | Q13: =_xlfn.XLOOKUP(M13,MA!C:C,MA!IG:IG,"") | R13: =_xlfn.XLOOKUP(M13,MA!C:C,MA!IS:IS,"") | S13: =_xlfn.XLOOKUP(M13,MA!C:C,MA!D:D,"") | T13: =_xlfn.XLOOKUP(M13,MA!C:C,MA!K:K,"") | U13: =_xlfn.XLOOKUP(M13,MA!C:C,MA!L:L,"") | V13: =(T13-S13)*100/(T13-U13) -> #VALUE! | Z13: {=_xlfn.IFS(AND(O13>0,P13>=0),"Y",AND(O13<0,P13<=0),"N",AND(O13>0),"W",AND(O13=0,P13>0),"W",TRUE,"")} -> Y | AB13: =AB12 + TIME(9,30,0) -> 46141.396 | AC13: Market Close Start Date and Time
A14: Econ.Ind 11 | B14: 11 | C14: {=INDEX(_xlfn._xlws.SORT(_xlfn._xlws.FILTER(Data!$C:$H, (Data!$L:$L="Y"),""),3),B14)} -> ADP payrolls | D14: 46148 | E14: 5 | F14: BEARISH | G14: 46147 | H14: 46147 | K14: High Yield | L14: =_xlfn.XLOOKUP(M14,MA!C:C,MA!H:H,"") | M14: HYG | N14: HYG | O14: =_xlfn.XLOOKUP(M14,MA!C:C,MA!VP:VP,"") | P14: =_xlfn.XLOOKUP(M14,MA!C:C,MA!VQ:VQ,"") | Q14: =_xlfn.XLOOKUP(M14,MA!C:C,MA!IG:IG,"") | R14: =_xlfn.XLOOKUP(M14,MA!C:C,MA!IS:IS,"") | S14: =_xlfn.XLOOKUP(M14,MA!C:C,MA!D:D,"") | T14: =_xlfn.XLOOKUP(M14,MA!C:C,MA!K:K,"") | U14: =_xlfn.XLOOKUP(M14,MA!C:C,MA!L:L,"") | V14: =(T14-S14)*100/(T14-U14) -> #VALUE! | Z14: {=_xlfn.IFS(AND(O14>0,P14>=0),"Y",AND(O14<0,P14<=0),"N",AND(O14>0),"W",AND(O14=0,P14>0),"W",TRUE,"")} -> Y | AB14: =AB12 + TIME(16,0,0) -> 46141.667 | AC14: Market Close End Date and Time
A15: Econ.Ind 12 | B15: 12 | C15: {=INDEX(_xlfn._xlws.SORT(_xlfn._xlws.FILTER(Data!$C:$H, (Data!$L:$L="Y"),""),3),B15)} -> New Home Sales | D15: 46148 | E15: 5 | F15: 0 | G15: 46147 | H15: 46147 | K15: Investment Grade Corporate Bond ETF | L15: =_xlfn.XLOOKUP(M15,MA!C:C,MA!H:H,"") | M15: LQD | N15: LQD | O15: =_xlfn.XLOOKUP(M15,MA!C:C,MA!VP:VP,"") | P15: =_xlfn.XLOOKUP(M15,MA!C:C,MA!VQ:VQ,"") | Q15: =_xlfn.XLOOKUP(M15,MA!C:C,MA!IG:IG,"") | R15: =_xlfn.XLOOKUP(M15,MA!C:C,MA!IS:IS,"") | S15: =_xlfn.XLOOKUP(M15,MA!C:C,MA!D:D,"") | T15: =_xlfn.XLOOKUP(M15,MA!C:C,MA!K:K,"") | U15: =_xlfn.XLOOKUP(M15,MA!C:C,MA!L:L,"") | V15: =(T15-S15)*100/(T15-U15) -> #VALUE! | Z15: {=_xlfn.IFS(AND(O15>0,P15>=0),"Y",AND(O15<0,P15<=0),"N",AND(O15>0),"W",AND(O15=0,P15>0),"W",TRUE,"")} -> Y | AB15: =WORKDAY(Dash!$AB$12,1,Data!$O$2:$O$31) -> 46142 | AC15: Next Close Date
A16: Econ.Ind 13 | B16: 13 | C16: {=INDEX(_xlfn._xlws.SORT(_xlfn._xlws.FILTER(Data!$C:$H, (Data!$L:$L="Y"),""),3),B16)} -> U.S. Michigan Consumer Sentiment (2 Fridy of M) | D16: 46150 | E16: 7 | F16: BEARISH | G16: 46149 | H16: 46149 | O16: =_xlfn.XLOOKUP(M16,MA!C:C,MA!VP:VP,"") -> 0 | P16: =_xlfn.XLOOKUP(M16,MA!C:C,MA!VQ:VQ,"") -> 0 | Q16: =_xlfn.XLOOKUP(M16,MA!C:C,MA!IG:IG,"") -> 0 | R16: =_xlfn.XLOOKUP(M16,MA!C:C,MA!IS:IS,"") -> 0 | AB16: =AB15 + TIME(9,30,0) -> 46142.396 | AC16: Next Close Start Date and Time
K17: 30-Year U.S. Treasury Yield | L17: =_xlfn.XLOOKUP(M17,MA!C:C,MA!H:H,"") | M17: ^TYX | N17: TYX:CGI | O17: =_xlfn.XLOOKUP(M17,MA!C:C,MA!VP:VP,"") | P17: =_xlfn.XLOOKUP(M17,MA!C:C,MA!VQ:VQ,"") | Q17: =_xlfn.XLOOKUP(M17,MA!C:C,MA!IG:IG,"") | R17: =_xlfn.XLOOKUP(M17,MA!C:C,MA!IS:IS,"") | S17: =_xlfn.XLOOKUP(M17,MA!C:C,MA!D:D,0)/10 -> 0 | T17: =_xlfn.XLOOKUP(M17,MA!C:C,MA!K:K,"") | U17: =_xlfn.XLOOKUP(M17,MA!C:C,MA!L:L,"") | V17: =(S17-U17)*100/(T17-U17) -> #VALUE! | Z17: {=_xlfn.IFS(O17>0,"Y",O17<0,"N",TRUE,"")} -> Y | AB17: =AB15 + TIME(16,0,0) -> 46142.667 | AC17: Next Close End Date and Time
K18: 10-Year U.S. Treasury Yield | L18: =_xlfn.XLOOKUP(M18,MA!C:C,MA!H:H,"") | M18: ^TNX | N18: TNX:CGI | O18: =_xlfn.XLOOKUP(M18,MA!C:C,MA!VP:VP,"") | P18: =_xlfn.XLOOKUP(M18,MA!C:C,MA!VQ:VQ,"") | Q18: =_xlfn.XLOOKUP(M18,MA!C:C,MA!IG:IG,"") | R18: =_xlfn.XLOOKUP(M18,MA!C:C,MA!IS:IS,"") | S18: =_xlfn.XLOOKUP(M18,MA!C:C,MA!D:D,0)/10 -> 0 | T18: =_xlfn.XLOOKUP(M18,MA!C:C,MA!K:K,"") | U18: =_xlfn.XLOOKUP(M18,MA!C:C,MA!L:L,"") | V18: =(S18-U18)*100/(T18-U18) -> #VALUE! | Z18: {=_xlfn.IFS(O18>0,"Y",O18<0,"N",TRUE,"")} -> Y | AB18: =_xlfn.MAXIFS(TW!B:B,TW!B:B,"<=" & AB16) -> 46141.688 | AC18: TOS Weekly export Date
K19: 2-Year U.S. Treasury Yield | L19: =_xlfn.XLOOKUP(MA!#REF!&M19,Y!$D:$D,Y!$M:$M) -> #REF! | M19: 2YY=F | N19: DGS2:FRED | O19: =_xlfn.XLOOKUP(M19,MA!C:C,MA!VP:VP,"") | P19: =_xlfn.XLOOKUP(M19,MA!C:C,MA!VQ:VQ,"") | Q19: =_xlfn.XLOOKUP(M19,MA!C:C,MA!IG:IG,"") | R19: =_xlfn.XLOOKUP(M19,MA!C:C,MA!IS:IS,"") | S19: =_xlfn.XLOOKUP($AB$23&M19,Y!$D:$D,Y!$K:$K) -> #N/A | T19: =_xlfn.XLOOKUP(N19,RR!F:F,RR!I:I) -> #N/A | U19: =_xlfn.XLOOKUP(N19,RR!F:F,RR!J:J) -> #N/A | V19: =(S19-U19)*100/(T19-U19) -> #N/A | Z19: {=_xlfn.IFS(O19>0,"Y",O19<0,"N",TRUE,"")} -> Y | AB19: =_xlfn.MAXIFS(TD!B:B,TD!B:B,">=" & AB14,TD!B:B,"<=" & AB16) -> 46141.688 | AC19: TOS Daily export Date
B20: Ticker | C20: Earnings Days | F20: HE OL | G20: TrTn OL | O20: =_xlfn.XLOOKUP(M20,MA!C:C,MA!VP:VP,"") -> 0 | P20: =_xlfn.XLOOKUP(M20,MA!C:C,MA!VQ:VQ,"") -> 0 | Q20: =_xlfn.XLOOKUP(M20,MA!C:C,MA!IG:IG,"") -> 0 | R20: =_xlfn.XLOOKUP(M20,MA!C:C,MA!IS:IS,"") -> 0 | AB20: =_xlfn.MAXIFS(TO!B:B,TO!B:B,">=" & AN5,TO!B:B,"<=" & AB16) -> 46139.688 | AC20: TOS Other export Date
B21: {=_xlfn._xlws.SORT(_xlfn._xlws.FILTER(MA!JA2:JB179,(MA!JB2:JB179>=0)*(MA!JB2:JB179<7)*(MA!UY2:UY179=1)),2,1)} -> #VALUE! | F21: =IF(B21<>"",_xlfn.XLOOKUP(B21,MA!C:C,MA!VP:VP,""),"") -> #VALUE! | G21: =IF(B21<>"",_xlfn.XLOOKUP(B21,MA!C:C,MA!VQ:VQ,""),"") -> #VALUE! | K21: US Dollar | L21: =_xlfn.XLOOKUP(M21,MA!C:C,MA!H:H,"") | M21: ^NYICDX | N21: $DXY | O21: =_xlfn.XLOOKUP(M21,MA!C:C,MA!VP:VP,"") | P21: =_xlfn.XLOOKUP(M21,MA!C:C,MA!VQ:VQ,"") | Q21: =_xlfn.XLOOKUP(M21,MA!C:C,MA!IG:IG,"") | R21: =_xlfn.XLOOKUP(M21,MA!C:C,MA!IS:IS,"") | S21: =_xlfn.XLOOKUP(M21,MA!C:C,MA!D:D,"") | T21: =_xlfn.XLOOKUP(M21,MA!C:C,MA!K:K,"") | U21: =_xlfn.XLOOKUP(M21,MA!C:C,MA!L:L,"") | V21: =(T21-S21)*100/(T21-U21) -> #VALUE! | X21: 100 | Y21: 105 | Z21: {=_xlfn.IFS(AND(O21>0,P21>=0),"Y",AND(O21<0,P21<=0),"N",AND(O21>0),"W",AND(O21=0,P21>0),"W",TRUE,"")} -> Y | AB21: =_xlfn.MAXIFS(TL!B:B,TL!B:B,">=" & AB13,TL!B:B,"<=" & AB17) -> 46141.688 | AC21: TOS Latest export Date
F22: =IF(B22<>"",_xlfn.XLOOKUP(B22,MA!C:C,MA!VP:VP,""),"") | G22: =IF(B22<>"",_xlfn.XLOOKUP(B22,MA!C:C,MA!VQ:VQ,""),"") | K22: Euro to U.S. Dollar | L22: =_xlfn.XLOOKUP(M22,MA!C:C,MA!H:H,"") | M22: EURUSD=X | N22: /6E | O22: =_xlfn.XLOOKUP(M22,MA!C:C,MA!VP:VP,"") | P22: =_xlfn.XLOOKUP(M22,MA!C:C,MA!VQ:VQ,"") | Q22: =_xlfn.XLOOKUP(M22,MA!C:C,MA!IG:IG,"") | R22: =_xlfn.XLOOKUP(M22,MA!C:C,MA!IS:IS,"") | S22: =_xlfn.XLOOKUP(M22,MA!C:C,MA!D:D,"") | T22: =_xlfn.XLOOKUP(M22,MA!C:C,MA!K:K,"") | U22: =_xlfn.XLOOKUP(M22,MA!C:C,MA!L:L,"") | V22: =(T22-S22)*100/(T22-U22) -> #VALUE! | Z22: {=_xlfn.IFS(AND(O22>0,P22>=0),"Y",AND(O22<0,P22<=0),"N",AND(O22>0),"W",AND(O22=0,P22>0),"W",TRUE,"")} -> Y | AB22: =_xlfn.MAXIFS(Y!B:B,Y!B:B,">=" & AB14,Y!B:B,"<=" & AB16) -> 46141.688 | AC22: Y Market Close export Date
F23: =IF(B23<>"",_xlfn.XLOOKUP(B23,MA!C:C,MA!VP:VP,""),"") | G23: =IF(B23<>"",_xlfn.XLOOKUP(B23,MA!C:C,MA!VQ:VQ,""),"") | K23: U.S. Dollar to Japanese Yen | L23: =_xlfn.XLOOKUP(M23,MA!C:C,MA!H:H,"") | M23: JPYUSD=X | N23: /6J | O23: =_xlfn.XLOOKUP(M23,MA!C:C,MA!VP:VP,"") | P23: =_xlfn.XLOOKUP(M23,MA!C:C,MA!VQ:VQ,"") | Q23: =_xlfn.XLOOKUP(M23,MA!C:C,MA!IG:IG,"") | R23: =_xlfn.XLOOKUP(M23,MA!C:C,MA!IS:IS,"") | S23: =_xlfn.XLOOKUP(M23,MA!C:C,MA!D:D,"") | T23: =_xlfn.XLOOKUP(M23,MA!C:C,MA!K:K,"") | U23: =_xlfn.XLOOKUP(M23,MA!C:C,MA!L:L,"") | V23: =(T23-S23)*100/(T23-U23) -> #VALUE! | Z23: {=_xlfn.IFS(AND(O23>0,P23>=0),"Y",AND(O23<0,P23<=0),"N",AND(O23>0),"W",AND(O23=0,P23>0),"W",TRUE,"")} -> Y | AB23: =_xlfn.MAXIFS(Y!B:B,Y!B:B,">=" & AB11,Y!B:B,"<=" & AB17) -> 46141.688 | AC23: Y Latest export Date
F24: =IF(B24<>"",_xlfn.XLOOKUP(B24,MA!C:C,MA!VP:VP,""),"") | G24: =IF(B24<>"",_xlfn.XLOOKUP(B24,MA!C:C,MA!VQ:VQ,""),"") | K24: British Pound to U.S. Dollar | L24: =_xlfn.XLOOKUP(M24,MA!C:C,MA!H:H,"") | M24: GBPUSD=X | N24: /6B | O24: =_xlfn.XLOOKUP(M24,MA!C:C,MA!VP:VP,"") | P24: =_xlfn.XLOOKUP(M24,MA!C:C,MA!VQ:VQ,"") | Q24: =_xlfn.XLOOKUP(M24,MA!C:C,MA!IG:IG,"") | R24: =_xlfn.XLOOKUP(M24,MA!C:C,MA!IS:IS,"") | S24: =_xlfn.XLOOKUP(M24,MA!C:C,MA!D:D,"") | T24: =_xlfn.XLOOKUP(M24,MA!C:C,MA!K:K,"") | U24: =_xlfn.XLOOKUP(M24,MA!C:C,MA!L:L,"") | V24: =(T24-S24)*100/(T24-U24) -> #VALUE! | Z24: {=_xlfn.IFS(AND(O24>0,P24>=0),"Y",AND(O24<0,P24<=0),"N",AND(O24>0),"W",AND(O24=0,P24>0),"W",TRUE,"")} -> Y | AB24: =IF($AB$23>$AB$21,"Y","N") -> N | AC24: Latest Y or TOS (N)
F25: =IF(B25<>"",_xlfn.XLOOKUP(B25,MA!C:C,MA!VP:VP,""),"") | G25: =IF(B25<>"",_xlfn.XLOOKUP(B25,MA!C:C,MA!VQ:VQ,""),"") | K25: Canadian Dollar to U.S. Dollar | L25: =_xlfn.XLOOKUP(M25,MA!C:C,MA!H:H,"") | M25: CADUSD=X | N25: /6C | O25: =_xlfn.XLOOKUP(M25,MA!C:C,MA!VP:VP,"") | P25: =_xlfn.XLOOKUP(M25,MA!C:C,MA!VQ:VQ,"") | Q25: =_xlfn.XLOOKUP(M25,MA!C:C,MA!IG:IG,"") | R25: =_xlfn.XLOOKUP(M25,MA!C:C,MA!IS:IS,"") | S25: =_xlfn.XLOOKUP(M25,MA!C:C,MA!D:D,"") | T25: =_xlfn.XLOOKUP(M25,MA!C:C,MA!K:K,"") | U25: =_xlfn.XLOOKUP(M25,MA!C:C,MA!L:L,"") | V25: =(T25-S25)*100/(T25-U25) -> #VALUE! | Z25: {=_xlfn.IFS(AND(O25>0,P25>=0),"Y",AND(O25<0,P25<=0),"N",AND(O25>0),"W",AND(O25=0,P25>0),"W",TRUE,"")} -> Y | AB25: =IF($AB$21>$AB$19,"Y","N") -> N | AC25: Latest TOSL (Y) or TOSD(W) (N)
F26: =IF(B26<>"",_xlfn.XLOOKUP(B26,MA!C:C,MA!VP:VP,""),"") | G26: =IF(B26<>"",_xlfn.XLOOKUP(B26,MA!C:C,MA!VQ:VQ,""),"") | K26: German DAX Composite | L26: =_xlfn.XLOOKUP(M26,MA!C:C,MA!H:H,"") | M26: ^GDAXI | N26: GDAXI:DE | O26: =_xlfn.XLOOKUP(M26,MA!C:C,MA!VP:VP,"") | P26: =_xlfn.XLOOKUP(M26,MA!C:C,MA!VQ:VQ,"") | Q26: =_xlfn.XLOOKUP(M26,MA!C:C,MA!IG:IG,"") | R26: =_xlfn.XLOOKUP(M26,MA!C:C,MA!IS:IS,"") | S26: =_xlfn.XLOOKUP(M26,MA!C:C,MA!D:D,"") | T26: =_xlfn.XLOOKUP(M26,MA!C:C,MA!K:K,"") | U26: =_xlfn.XLOOKUP(M26,MA!C:C,MA!L:L,"") | V26: =(T26-S26)*100/(T26-U26) -> #VALUE! | Z26: {=_xlfn.IFS(AND(O26>0,P26>=0),"Y",AND(O26<0,P26<=0),"N",AND(O26>0),"W",AND(O26=0,P26>0),"W",TRUE,"")} -> Y
F27: =IF(B27<>"",_xlfn.XLOOKUP(B27,MA!C:C,MA!VP:VP,""),"") | G27: =IF(B27<>"",_xlfn.XLOOKUP(B27,MA!C:C,MA!VQ:VQ,""),"") | K27: Nikkei 225 Index | L27: =_xlfn.XLOOKUP(M27,MA!C:C,MA!H:H,"") | M27: ^N225 | N27: N225:JP | O27: =_xlfn.XLOOKUP(M27,MA!C:C,MA!VP:VP,"") | P27: =_xlfn.XLOOKUP(M27,MA!C:C,MA!VQ:VQ,"") | Q27: =_xlfn.XLOOKUP(M27,MA!C:C,MA!IG:IG,"") | R27: =_xlfn.XLOOKUP(M27,MA!C:C,MA!IS:IS,"") | S27: =_xlfn.XLOOKUP(M27,MA!C:C,MA!D:D,"") | T27: =_xlfn.XLOOKUP(M27,MA!C:C,MA!K:K,"") | U27: =_xlfn.XLOOKUP(M27,MA!C:C,MA!L:L,"") | V27: =(T27-S27)*100/(T27-U27) -> #VALUE! | Z27: {=_xlfn.IFS(AND(O27>0,P27>=0),"Y",AND(O27<0,P27<=0),"N",AND(O27>0),"W",AND(O27=0,P27>0),"W",TRUE,"")} -> Y | AB27: =_xlfn.XLOOKUP("Y",HQds!$D$2:$D$25,HQds!$E$2:$E$25) -> Quad 2 | AC27: Monthly Quad
F28: =IF(B28<>"",_xlfn.XLOOKUP(B28,MA!C:C,MA!VP:VP,""),"") | G28: =IF(B28<>"",_xlfn.XLOOKUP(B28,MA!C:C,MA!VQ:VQ,""),"") | K28: Sectors | O28: =_xlfn.XLOOKUP(M28,MA!C:C,MA!VP:VP,"") -> 0 | P28: =_xlfn.XLOOKUP(M28,MA!C:C,MA!VQ:VQ,"") -> 0 | Q28: =_xlfn.XLOOKUP(M28,MA!C:C,MA!IG:IG,"") -> 0 | R28: =_xlfn.XLOOKUP(M28,MA!C:C,MA!IS:IS,"") -> 0 | AB28: =_xlfn.XLOOKUP("Y",HQds!$L$2:$L$25,HQds!$M$2:$M$25) -> Quad 3 | AC28: Quarterly Quad
F29: =IF(B29<>"",_xlfn.XLOOKUP(B29,MA!C:C,MA!VP:VP,""),"") | G29: =IF(B29<>"",_xlfn.XLOOKUP(B29,MA!C:C,MA!VQ:VQ,""),"") | K29: Communication Services | L29: =_xlfn.XLOOKUP(M29,MA!C:C,MA!H:H,"") | M29: XLC | N29: XLC | O29: =_xlfn.XLOOKUP(M29,MA!C:C,MA!VP:VP,"") | P29: =_xlfn.XLOOKUP(M29,MA!C:C,MA!VQ:VQ,"") | Q29: =_xlfn.XLOOKUP(M29,MA!C:C,MA!IG:IG,"") | R29: =_xlfn.XLOOKUP(M29,MA!C:C,MA!IS:IS,"") | S29: =_xlfn.XLOOKUP(M29,MA!C:C,MA!D:D,"") | T29: =_xlfn.XLOOKUP(M29,MA!C:C,MA!K:K,"") | U29: =_xlfn.XLOOKUP(M29,MA!C:C,MA!L:L,"") | V29: =(T29-S29)*100/(T29-U29) -> #VALUE! | Z29: {=_xlfn.IFS(SUM(O29:R29)=0,"",AND(O29:R29>=0),"Y",AND(O29:R29<=0),"N",TRUE,"W")}
F30: =IF(B30<>"",_xlfn.XLOOKUP(B30,MA!C:C,MA!VP:VP,""),"") | G30: =IF(B30<>"",_xlfn.XLOOKUP(B30,MA!C:C,MA!VQ:VQ,""),"") | K30: Consumer Discretionary | L30: =_xlfn.XLOOKUP(M30,MA!C:C,MA!H:H,"") | M30: XLY | N30: XLY | O30: =_xlfn.XLOOKUP(M30,MA!C:C,MA!VP:VP,"") | P30: =_xlfn.XLOOKUP(M30,MA!C:C,MA!VQ:VQ,"") | Q30: =_xlfn.XLOOKUP(M30,MA!C:C,MA!IG:IG,"") | R30: =_xlfn.XLOOKUP(M30,MA!C:C,MA!IS:IS,"") | S30: =_xlfn.XLOOKUP(M30,MA!C:C,MA!D:D,"") | T30: =_xlfn.XLOOKUP(M30,MA!C:C,MA!K:K,"") | U30: =_xlfn.XLOOKUP(M30,MA!C:C,MA!L:L,"") | V30: =(T30-S30)*100/(T30-U30) -> #VALUE! | Z30: {=_xlfn.IFS(SUM(O30:R30)=0,"",AND(O30:R30>=0),"Y",AND(O30:R30<=0),"N",TRUE,"W")} | AB30: {=REPLACE(LEFT(CELL("filename",A1),FIND("]",CELL("filename",A1))-1),1,FIND("[",CELL("filename",A1)),"")} -> Tickers 2026-04-30.xlsx | AC30: Filename
F31: =IF(B31<>"",_xlfn.XLOOKUP(B31,MA!C:C,MA!VP:VP,""),"") | G31: =IF(B31<>"",_xlfn.XLOOKUP(B31,MA!C:C,MA!VQ:VQ,""),"") | K31: Consumer Staples | L31: =_xlfn.XLOOKUP(M31,MA!C:C,MA!H:H,"") | M31: XLP | N31: XLP | O31: =_xlfn.XLOOKUP(M31,MA!C:C,MA!VP:VP,"") | P31: =_xlfn.XLOOKUP(M31,MA!C:C,MA!VQ:VQ,"") | Q31: =_xlfn.XLOOKUP(M31,MA!C:C,MA!IG:IG,"") | R31: =_xlfn.XLOOKUP(M31,MA!C:C,MA!IS:IS,"") | S31: =_xlfn.XLOOKUP(M31,MA!C:C,MA!D:D,"") | T31: =_xlfn.XLOOKUP(M31,MA!C:C,MA!K:K,"") | U31: =_xlfn.XLOOKUP(M31,MA!C:C,MA!L:L,"") | V31: =(T31-S31)*100/(T31-U31) -> #VALUE! | Z31: {=_xlfn.IFS(SUM(O31:R31)=0,"",AND(O31:R31>=0),"Y",AND(O31:R31<=0),"N",TRUE,"W")} | AB31: =DATEVALUE(MID(AB30,FIND(" ",AB30)+1,10)) -> 46142 | AC31: Filedate
F32: =IF(B32<>"",_xlfn.XLOOKUP(B32,MA!C:C,MA!VP:VP,""),"") | G32: =IF(B32<>"",_xlfn.XLOOKUP(B32,MA!C:C,MA!VQ:VQ,""),"") | K32: Energy | L32: =_xlfn.XLOOKUP(M32,MA!C:C,MA!H:H,"") | M32: XLE | N32: XLE | O32: =_xlfn.XLOOKUP(M32,MA!C:C,MA!VP:VP,"") | P32: =_xlfn.XLOOKUP(M32,MA!C:C,MA!VQ:VQ,"") | Q32: =_xlfn.XLOOKUP(M32,MA!C:C,MA!IG:IG,"") | R32: =_xlfn.XLOOKUP(M32,MA!C:C,MA!IS:IS,"") | S32: =_xlfn.XLOOKUP(M32,MA!C:C,MA!D:D,"") | T32: =_xlfn.XLOOKUP(M32,MA!C:C,MA!K:K,"") | U32: =_xlfn.XLOOKUP(M32,MA!C:C,MA!L:L,"") | V32: =(T32-S32)*100/(T32-U32) -> #VALUE! | Z32: {=_xlfn.IFS(SUM(O32:R32)=0,"",AND(O32:R32>=0),"Y",AND(O32:R32<=0),"N",TRUE,"W")}
F33: =IF(B33<>"",_xlfn.XLOOKUP(B33,MA!C:C,MA!VP:VP,""),"") | G33: =IF(B33<>"",_xlfn.XLOOKUP(B33,MA!C:C,MA!VQ:VQ,""),"") | K33: Financials | L33: =_xlfn.XLOOKUP(M33,MA!C:C,MA!H:H,"") | M33: XLF | N33: XLF | O33: =_xlfn.XLOOKUP(M33,MA!C:C,MA!VP:VP,"") | P33: =_xlfn.XLOOKUP(M33,MA!C:C,MA!VQ:VQ,"") | Q33: =_xlfn.XLOOKUP(M33,MA!C:C,MA!IG:IG,"") | R33: =_xlfn.XLOOKUP(M33,MA!C:C,MA!IS:IS,"") | S33: =_xlfn.XLOOKUP(M33,MA!C:C,MA!D:D,"") | T33: =_xlfn.XLOOKUP(M33,MA!C:C,MA!K:K,"") | U33: =_xlfn.XLOOKUP(M33,MA!C:C,MA!L:L,"") | V33: =(T33-S33)*100/(T33-U33) -> #VALUE! | Z33: {=_xlfn.IFS(SUM(O33:R33)=0,"",AND(O33:R33>=0),"Y",AND(O33:R33<=0),"N",TRUE,"W")} | AB33: 2.59 | AC33: Dec CPI
F34: =IF(B34<>"",_xlfn.XLOOKUP(B34,MA!C:C,MA!VP:VP,""),"") | G34: =IF(B34<>"",_xlfn.XLOOKUP(B34,MA!C:C,MA!VQ:VQ,""),"") | K34: Health Care | L34: =_xlfn.XLOOKUP(M34,MA!C:C,MA!H:H,"") | M34: XLV | N34: XLV | O34: =_xlfn.XLOOKUP(M34,MA!C:C,MA!VP:VP,"") | P34: =_xlfn.XLOOKUP(M34,MA!C:C,MA!VQ:VQ,"") | Q34: =_xlfn.XLOOKUP(M34,MA!C:C,MA!IG:IG,"") | R34: =_xlfn.XLOOKUP(M34,MA!C:C,MA!IS:IS,"") | S34: =_xlfn.XLOOKUP(M34,MA!C:C,MA!D:D,"") | T34: =_xlfn.XLOOKUP(M34,MA!C:C,MA!K:K,"") | U34: =_xlfn.XLOOKUP(M34,MA!C:C,MA!L:L,"") | V34: =(T34-S34)*100/(T34-U34) -> #VALUE! | Z34: {=_xlfn.IFS(SUM(O34:R34)=0,"",AND(O34:R34>=0),"Y",AND(O34:R34<=0),"N",TRUE,"W")}
F35: =IF(B35<>"",_xlfn.XLOOKUP(B35,MA!C:C,MA!VP:VP,""),"") | G35: =IF(B35<>"",_xlfn.XLOOKUP(B35,MA!C:C,MA!VQ:VQ,""),"") | K35: Industrials | L35: =_xlfn.XLOOKUP(M35,MA!C:C,MA!H:H,"") | M35: XLI | N35: XLI | O35: =_xlfn.XLOOKUP(M35,MA!C:C,MA!VP:VP,"") | P35: =_xlfn.XLOOKUP(M35,MA!C:C,MA!VQ:VQ,"") | Q35: =_xlfn.XLOOKUP(M35,MA!C:C,MA!IG:IG,"") | R35: =_xlfn.XLOOKUP(M35,MA!C:C,MA!IS:IS,"") | S35: =_xlfn.XLOOKUP(M35,MA!C:C,MA!D:D,"") | T35: =_xlfn.XLOOKUP(M35,MA!C:C,MA!K:K,"") | U35: =_xlfn.XLOOKUP(M35,MA!C:C,MA!L:L,"") | V35: =(T35-S35)*100/(T35-U35) -> #VALUE! | Z35: {=_xlfn.IFS(SUM(O35:R35)=0,"",AND(O35:R35>=0),"Y",AND(O35:R35<=0),"N",TRUE,"W")}
F36: =IF(B36<>"",_xlfn.XLOOKUP(B36,MA!C:C,MA!VP:VP,""),"") | G36: =IF(B36<>"",_xlfn.XLOOKUP(B36,MA!C:C,MA!VQ:VQ,""),"") | K36: Information Technology | L36: =_xlfn.XLOOKUP(M36,MA!C:C,MA!H:H,"") | M36: XLK | N36: XLK | O36: =_xlfn.XLOOKUP(M36,MA!C:C,MA!VP:VP,"") | P36: =_xlfn.XLOOKUP(M36,MA!C:C,MA!VQ:VQ,"") | Q36: =_xlfn.XLOOKUP(M36,MA!C:C,MA!IG:IG,"") | R36: =_xlfn.XLOOKUP(M36,MA!C:C,MA!IS:IS,"") | S36: =_xlfn.XLOOKUP(M36,MA!C:C,MA!D:D,"") | T36: =_xlfn.XLOOKUP(M36,MA!C:C,MA!K:K,"") | U36: =_xlfn.XLOOKUP(M36,MA!C:C,MA!L:L,"") | V36: =(T36-S36)*100/(T36-U36) -> #VALUE! | Z36: {=_xlfn.IFS(SUM(O36:R36)=0,"",AND(O36:R36>=0),"Y",AND(O36:R36<=0),"N",TRUE,"W")}
F37: =IF(B37<>"",_xlfn.XLOOKUP(B37,MA!C:C,MA!VP:VP,""),"") | G37: =IF(B37<>"",_xlfn.XLOOKUP(B37,MA!C:C,MA!VQ:VQ,""),"") | K37: Materials | L37: =_xlfn.XLOOKUP(M37,MA!C:C,MA!H:H,"") | M37: XLB | N37: XLB | O37: =_xlfn.XLOOKUP(M37,MA!C:C,MA!VP:VP,"") | P37: =_xlfn.XLOOKUP(M37,MA!C:C,MA!VQ:VQ,"") | Q37: =_xlfn.XLOOKUP(M37,MA!C:C,MA!IG:IG,"") | R37: =_xlfn.XLOOKUP(M37,MA!C:C,MA!IS:IS,"") | S37: =_xlfn.XLOOKUP(M37,MA!C:C,MA!D:D,"") | T37: =_xlfn.XLOOKUP(M37,MA!C:C,MA!K:K,"") | U37: =_xlfn.XLOOKUP(M37,MA!C:C,MA!L:L,"") | V37: =(T37-S37)*100/(T37-U37) -> #VALUE! | Z37: {=_xlfn.IFS(SUM(O37:R37)=0,"",AND(O37:R37>=0),"Y",AND(O37:R37<=0),"N",TRUE,"W")}
F38: =IF(B38<>"",_xlfn.XLOOKUP(B38,MA!C:C,MA!VP:VP,""),"") | G38: =IF(B38<>"",_xlfn.XLOOKUP(B38,MA!C:C,MA!VQ:VQ,""),"") | K38: Real Estate | L38: =_xlfn.XLOOKUP(M38,MA!C:C,MA!H:H,"") | M38: XLRE | N38: XLRE | O38: =_xlfn.XLOOKUP(M38,MA!C:C,MA!VP:VP,"") | P38: =_xlfn.XLOOKUP(M38,MA!C:C,MA!VQ:VQ,"") | Q38: =_xlfn.XLOOKUP(M38,MA!C:C,MA!IG:IG,"") | R38: =_xlfn.XLOOKUP(M38,MA!C:C,MA!IS:IS,"") | S38: =_xlfn.XLOOKUP(M38,MA!C:C,MA!D:D,"") | T38: =_xlfn.XLOOKUP(M38,MA!C:C,MA!K:K,"") | U38: =_xlfn.XLOOKUP(M38,MA!C:C,MA!L:L,"") | V38: =(T38-S38)*100/(T38-U38) -> #VALUE! | Z38: {=_xlfn.IFS(SUM(O38:R38)=0,"",AND(O38:R38>=0),"Y",AND(O38:R38<=0),"N",TRUE,"W")}
F39: =IF(B39<>"",_xlfn.XLOOKUP(B39,MA!C:C,MA!VP:VP,""),"") | G39: =IF(B39<>"",_xlfn.XLOOKUP(B39,MA!C:C,MA!VQ:VQ,""),"") | K39: Utilities | L39: =_xlfn.XLOOKUP(M39,MA!C:C,MA!H:H,"") | M39: XLU | N39: XLU | O39: =_xlfn.XLOOKUP(M39,MA!C:C,MA!VP:VP,"") | P39: =_xlfn.XLOOKUP(M39,MA!C:C,MA!VQ:VQ,"") | Q39: =_xlfn.XLOOKUP(M39,MA!C:C,MA!IG:IG,"") | R39: =_xlfn.XLOOKUP(M39,MA!C:C,MA!IS:IS,"") | S39: =_xlfn.XLOOKUP(M39,MA!C:C,MA!D:D,"") | T39: =_xlfn.XLOOKUP(M39,MA!C:C,MA!K:K,"") | U39: =_xlfn.XLOOKUP(M39,MA!C:C,MA!L:L,"") | V39: =(T39-S39)*100/(T39-U39) -> #VALUE! | Z39: {=_xlfn.IFS(SUM(O39:R39)=0,"",AND(O39:R39>=0),"Y",AND(O39:R39<=0),"N",TRUE,"W")}
F40: =IF(B40<>"",_xlfn.XLOOKUP(B40,MA!C:C,MA!VP:VP,""),"") | G40: =IF(B40<>"",_xlfn.XLOOKUP(B40,MA!C:C,MA!VQ:VQ,""),"") | K40: Commodities | O40: =_xlfn.XLOOKUP(M40,MA!C:C,MA!VP:VP,"") -> 0 | P40: =_xlfn.XLOOKUP(M40,MA!C:C,MA!VQ:VQ,"") -> 0 | Q40: =_xlfn.XLOOKUP(M40,MA!C:C,MA!IG:IG,"") -> 0 | R40: =_xlfn.XLOOKUP(M40,MA!C:C,MA!IS:IS,"") -> 0
...

Sheet My

Sheet Y
A1: DateSymbol | B1: DateTime | C1: Sym | D1: DateSymbolTime | E1: Date | F1: Sequence | G1: Export Date | H1: Export Time | I1: Symbol | J1: Company Name | K1: Last Price | L1: Change | M1: Change (%) | N1: Open | O1: High | P1: Low | Q1: Short Ratio | R1: Float | S1: Shares Out
A2: =IF(I2="","",E2&I2) -> 46141ZM | B2: =E2 + TIME(LEFT(TEXT(F2,"0000"),2),RIGHT(TEXT(F2,"0000"),2),0) -> 46141.688 | C2: =IF(ISNUMBER(SEARCH("[",I2)),LEFT(I2,FIND("[",I2)-1),I2) -> ZM | D2: =IF(I2="","",B2&C2) -> 46141.6875ZM | E2: =G2 -> 46141 | F2: =H2 -> 1630 | G2: 46141 | H2: 1630 | I2: ZM | J2: Zoom Communications, Inc. | K2: 95.76 | L2: 4.62 | M2: 0.0507 | N2: 91.54 | O2: 96.51 | P2: 91.02 | Q2: 1.7 | R2: 260.232M | S2: 265.97M
A3: =IF(I3="","",E3&I3) -> 46141ZS | B3: =E3 + TIME(LEFT(TEXT(F3,"0000"),2),RIGHT(TEXT(F3,"0000"),2),0) -> 46141.688 | C3: =IF(ISNUMBER(SEARCH("[",I3)),LEFT(I3,FIND("[",I3)-1),I3) -> ZS | D3: =IF(I3="","",B3&C3) -> 46141.6875ZS | E3: =G3 -> 46141 | F3: =H3 -> 1630 | G3: 46141 | H3: 1630 | I3: ZS | J3: Zscaler, Inc. | K3: 134.73 | L3: -1.34 | M3: -0.0098 | N3: 135.12 | O3: 135.71 | P3: 131.76 | Q3: 3.53 | R3: 104.215M | S3: 160.791M

Sheet TL
A1: DateSymbol | B1: DateTime | C1: Sym | D1: DateSymbolTime | E1: Date | F1: Sequence | G1: Vlm | H1: ImpVolatility | I1: Export Date | J1: Export Time | K1: Symbol | L1: Last | M1: Net Chng | N1: %Change | O1: Open | P1: High | Q1: Low | R1: Volume | S1: RSI | T1: ImpVolatility
A2: =IF(K2="","",E2&K2) -> 46141ZM | B2: =E2 + TIME(LEFT(TEXT(F2,"0000"),2),RIGHT(TEXT(F2,"0000"),2),0) -> 46141.688 | C2: =IF(ISNUMBER(SEARCH("[",K2)),LEFT(K2,FIND("[",K2)-1),K2) -> ZM | D2: =IF(K2="","",B2&C2) -> 46141.6875ZM | E2: =I2 -> 46141 | F2: =J2 -> 1630 | G2: =IF(OR(K2="",R2="<empty>",F2<930),"",IF(F2<1600, R2*390/((INT(F2/100)*60 + MOD(F2,100)) - 570),R2)) -> 6815835 | H2: =IF(J2="","",IF(T2="NaN",0,T2)) -> 0.59 | I2: 46141 | J2: 1630 | K2: ZM | L2: 95.76 | M2: 4.62 | N2: 0.0507 | O2: 91.685 | P2: 96.51 | Q2: 91.02 | R2: 6815835 | S2: 69.17 | T2: 0.59
A3: =IF(K3="","",E3&K3) -> 46141ZS | B3: =E3 + TIME(LEFT(TEXT(F3,"0000"),2),RIGHT(TEXT(F3,"0000"),2),0) -> 46141.688 | C3: =IF(ISNUMBER(SEARCH("[",K3)),LEFT(K3,FIND("[",K3)-1),K3) -> ZS | D3: =IF(K3="","",B3&C3) -> 46141.6875ZS | E3: =I3 -> 46141 | F3: =J3 -> 1630 | G3: =IF(OR(K3="",R3="<empty>",F3<930),"",IF(F3<1600, R3*390/((INT(F3/100)*60 + MOD(F3,100)) - 570),R3)) -> 1339176 | H3: =IF(J3="","",IF(T3="NaN",0,T3)) -> 0.76 | I3: 46141 | J3: 1630 | K3: ZS | L3: 134.73 | M3: -1.34 | N3: -0.0098 | O3: 135.12 | P3: 135.715 | Q3: 131.74 | R3: 1339176 | S3: 46.06 | T3: 0.76

Sheet TD
A1: DateSymbol | B1: DateTime | C1: Sym | D1: DateSymbolTime | E1: Date1 | F1: Sequence | G1: DSKey | H1: DS Sequence | I1: BB_Bot_15d | J1: BB_Bot_7d | K1: BB_Bot_3d | L1: BB_Bot_Prev | M1: BB_Top_15d | N1: BB_Top_7d | O1: BB_Top_3d | P1: BB_Top_Prev | Q1: IVPercentile | R1: HVPercentile | S1: RangeCompression | T1: D_RSI | U1: D_RSI3 | V1: D_RSI7 | W1: D_RSIDirection | X1: D_HV | Y1: D_HV3 | Z1: D_HV7 | AA1: D_HVDirection | AB1: D_IV | AC1: D_IV3 | AD1: D_IV7 | AE1: D_IVDirection | AF1: D_IVP3 | AG1: D_IVP7 | AH1: D_IVPDirection | AI1: D_IVPMax10 | AJ1: D_IV_to_HV | AK1: D_Vlt_RuleCode | AL1: D_Vlt_Caution | AM1: Export Date | AN1: Export Time | AO1: Symbol | AP1: Last | AQ1: Net Chng | AR1: %Change | AS1: Open | AT1: High | AU1: Low | AV1: RSI | AW1: HistoricalVolatility | AX1: ImpVolatility | AY1: A_TrendValue | AZ1: A_TradeValue | BA1: A_BB_Bottom | BB1: A_BB_Top | BC1: A_BB_Streak | BD1: A_BBHighLow | BE1: A_BBHighLowDays | BF1: A_IVPercentile | BG1: A_HVPercentile | BH1: A_BB_Top_Slope | BI1: A_BB_Bot_Slope
A2: =IF(AO2="","",E2&AO2) -> 46141ZM | B2: =E2 + TIME(LEFT(TEXT(F2,"0000"),2),RIGHT(TEXT(F2,"0000"),2),0) -> 46141.688 | C2: =IF(ISNUMBER(SEARCH("[",AO2)),LEFT(AO2,FIND("[",AO2)-1),AO2) -> ZM | D2: =IF(AO2="","",B2&C2) -> 46141.6875ZM | E2: =AM2 -> 46141 | F2: =AN2 -> 1630 | G2: =H2&C2 -> 1ZM | H2: =1 -> 1 | I2: {=_xlfn.XLOOKUP((H2-15)&C2, G$1:G1, BA$1:BA1, 0, 0, -1)} -> 0 | J2: {=_xlfn.XLOOKUP((H2-7)&C2, G$1:G1, BA$1:BA1, 0, 0, -1)} -> 0 | K2: {=_xlfn.XLOOKUP((H2-3)&C2,G$1:G1,BA$1:BA1,0,0,-1)} -> 0 | L2: {=_xlfn.XLOOKUP(C2, C$1:C1, BA$1:BA1, 0, 0, -1)} -> 0 | M2: {=_xlfn.XLOOKUP((H2-15)&C2,G$1:G1,BB$1:BB1,0,0,-1)} -> 0 | N2: {=_xlfn.XLOOKUP((H2-7)&C2,G$1:G1,BB$1:BB1,0,0,-1)} -> 0 | O2: {=_xlfn.XLOOKUP((H2-3)&C2, G$1:G1, BB$1:BB1, 0, 0, -1)} -> 0 | P2: {=_xlfn.XLOOKUP(C2, C$1:C1, BB$1:BB1, 0, 0, -1)} -> 0 | Q2: =IF(AO2="","",IF(BF2="NaN",0,BF2)) -> 96.4 | R2: =IF(AO2="","",IF(BG2="NaN",0,BG2)) -> 74.1 | S2: {=(MAX(_xlfn.TAKE(_xlfn._xlws.FILTER($AT$2:$AT2, $C$2:$C2=$C2), -10)) - MIN(_xlfn.TAKE(_xlfn._xlws.FILTER($AU$2:$AU2, $C$2:$C2=$C2), -10)))/AP2} -> 0.057330827 | T2: =AV2 -> 69.17 | U2: {=AVERAGE(_xlfn.TAKE(_xlfn._xlws.FILTER(AV$2:AV2, C$2:C2=C2), -3))} -> 69.17 | V2: {=AVERAGE(_xlfn.TAKE(_xlfn._xlws.FILTER(AV$2:AV2, C$2:C2=C2), -7))} -> 69.17 | W2: {=_xlfn.IFS(OR(U2=0, V2=0), 0, (U2-V2) > 1, 1, (U2-V2) < -1, -1, TRUE, 0)} -> 0 | X2: =AW2 -> 0.46 | Y2: {=AVERAGE(_xlfn.TAKE(_xlfn._xlws.FILTER(AW$2:AW2, C$2:C2=C2), -3))} -> 0.46 | Z2: {=AVERAGE(_xlfn.TAKE(_xlfn._xlws.FILTER(AW$2:AW2, C$2:C2=C2), -7))} -> 0.46 | AA2: {=_xlfn.IFS(OR(Y2=0, Z2=0), 0, (Y2-Z2)/Z2 > 0.03, 1, (Y2-Z2)/Z2 < -0.03, -1, TRUE, 0)} -> 0 | AB2: =IF(AN2="","",IF(AX2="NaN",0,AX2)) -> 0.59 | AC2: {=AVERAGE(_xlfn.TAKE(_xlfn._xlws.FILTER(AB$2:AB2, C$2:C2=C2), -3))} -> 0.59 | AD2: {=AVERAGE(_xlfn.TAKE(_xlfn._xlws.FILTER(AB$2:AB2, $C$2:$C2=$C2), -7))} -> 0.59 | AE2: {=_xlfn.IFS(OR(AC2=0, AD2=0), 0, (AC2-AD2)/AD2 > 0.03, 1, (AC2-AD2)/AD2 < -0.03, -1, TRUE, 0)} -> 0 | AF2: {=AVERAGE(_xlfn.TAKE(_xlfn._xlws.FILTER($Q$2:$Q2, $C$2:$C2=$C2), -3))} -> 96.4 | AG2: {=AVERAGE(_xlfn.TAKE(_xlfn._xlws.FILTER($Q$2:$Q2, $C$2:$C2=$C2), -7))} -> 96.4 | AH2: {=_xlfn.IFS(OR(AF2=0, AG2=0), 0, (AF2-AG2) > 1, 1, (AF2-AG2) < -1, -1, TRUE, 0)} -> 0 | AI2: {=MAX(_xlfn.TAKE(_xlfn._xlws.FILTER($Q$2:$Q2, $C$2:$C2=$C2), -10))} -> 96.4 | AJ2: =IF(X2=0,0,AB2/X2) -> 1.2826087 | AK2: {=_xlfn.IFS( OR(Q2=0,X2=0,AB2=0),"", AND(Q2>90,W2<=0,OR((X2/Z2)>1.25,(Y2/Z2)>1.1,(AC2/AD2)>1.1)),1, AND(Q2>60,AJ2>2,AE2<0),2, AND(Q2<60,AA2<0,AE2>0,W2<0),3, AND(Q2>40,(Y2/Z2)>1.25,AA2<=0),4, AND(Q2>25,AA2<0,AE2<0,W2<0),5, AND(Q2<50,AA2<0,AE2<=0,W2<=0),6, AND(Q2<10,R2<=10,AH2<=0,S2<0.03),7, AND(Q2>60,AI2>=80,(AI2-Q2)>10,W2>0,AE2<0),8, AND(Q2<25,AA2>0,AE2>0,W2>0,AH2>0),9, AND(Q2<60,W2>0,AA2>=0,AE2>=0,T2>U2,T2>V2),10, TRUE,"" )} | AL2: {=_xlfn.IFS( OR(Q2=0,X2=0,AB2=0),"", Q2 > 90, "IVPXtrm", X2 / Z2 > 1.25, "HV1Spke", Y2 / Z2 > 1.25, "HV3Spke", AB2 / AD2 > 1.25, "IV1Spke", AC2 / AD2 > 1.25, "IV3Spke", AJ2 > 2, "HiIV2HV", AND(S2 < 0.03, X2 / Z2 > 1.25), "IVExpn", TRUE,"" )} -> IVPXtrm | AM2: 46141 | AN2: 1630 | AO2: ZM | AP2: 95.76 | AQ2: 4.62 | AR2: 0.0507 | AS2: 91.685 | AT2: 96.51 | AU2: 91.02 | AV2: 69.17 | AW2: 0.46 | AX2: 0.59 | AY2: 87.19 | AZ2: 77.02 | BA2: 83.77 | BB2: 98.86 | BC2: 8213.01 | BD2: 9651.01 | BE2: 6.14 | BF2: 96.4 | BG2: 74.1 | BH2: 9.2 | BI2: 6.8
A3: =IF(AO3="","",E3&AO3) -> 46141ZS | B3: =E3 + TIME(LEFT(TEXT(F3,"0000"),2),RIGHT(TEXT(F3,"0000"),2),0) -> 46141.688 | C3: =IF(ISNUMBER(SEARCH("[",AO3)),LEFT(AO3,FIND("[",AO3)-1),AO3) -> ZS | D3: =IF(AO3="","",B3&C3) -> 46141.6875ZS | E3: =AM3 -> 46141 | F3: =AN3 -> 1630 | G3: =H3&C3 -> 1ZS | H3: =1 -> 1 | I3: {=_xlfn.XLOOKUP((H3-15)&C3, G$1:G2, BA$1:BA2, 0, 0, -1)} -> 0 | J3: {=_xlfn.XLOOKUP((H3-7)&C3, G$1:G2, BA$1:BA2, 0, 0, -1)} -> 0 | K3: {=_xlfn.XLOOKUP((H3-3)&C3,G$1:G2,BA$1:BA2,0,0,-1)} -> 0 | L3: {=_xlfn.XLOOKUP(C3, C$1:C2, BA$1:BA2, 0, 0, -1)} -> 0 | M3: {=_xlfn.XLOOKUP((H3-15)&C3,G$1:G2,BB$1:BB2,0,0,-1)} -> 0 | N3: {=_xlfn.XLOOKUP((H3-7)&C3,G$1:G2,BB$1:BB2,0,0,-1)} -> 0 | O3: {=_xlfn.XLOOKUP((H3-3)&C3, G$1:G2, BB$1:BB2, 0, 0, -1)} -> 0 | P3: {=_xlfn.XLOOKUP(C3, C$1:C2, BB$1:BB2, 0, 0, -1)} -> 0 | Q3: =IF(AO3="","",IF(BF3="NaN",0,BF3)) -> 97.3 | R3: =IF(AO3="","",IF(BG3="NaN",0,BG3)) -> 86.3 | S3: {=(MAX(_xlfn.TAKE(_xlfn._xlws.FILTER($AT$2:$AT3, $C$2:$C3=$C3), -10)) - MIN(_xlfn.TAKE(_xlfn._xlws.FILTER($AU$2:$AU3, $C$2:$C3=$C3), -10)))/AP3} -> 0.029503451 | T3: =AV3 -> 46.06 | U3: {=AVERAGE(_xlfn.TAKE(_xlfn._xlws.FILTER(AV$2:AV3, C$2:C3=C3), -3))} -> 46.06 | V3: {=AVERAGE(_xlfn.TAKE(_xlfn._xlws.FILTER(AV$2:AV3, C$2:C3=C3), -7))} -> 46.06 | W3: {=_xlfn.IFS(OR(U3=0, V3=0), 0, (U3-V3) > 1, 1, (U3-V3) < -1, -1, TRUE, 0)} -> 0 | X3: =AW3 -> 0.65 | Y3: {=AVERAGE(_xlfn.TAKE(_xlfn._xlws.FILTER(AW$2:AW3, C$2:C3=C3), -3))} -> 0.65 | Z3: {=AVERAGE(_xlfn.TAKE(_xlfn._xlws.FILTER(AW$2:AW3, C$2:C3=C3), -7))} -> 0.65 | AA3: {=_xlfn.IFS(OR(Y3=0, Z3=0), 0, (Y3-Z3)/Z3 > 0.03, 1, (Y3-Z3)/Z3 < -0.03, -1, TRUE, 0)} -> 0 | AB3: =IF(AN3="","",IF(AX3="NaN",0,AX3)) -> 0.76 | AC3: {=AVERAGE(_xlfn.TAKE(_xlfn._xlws.FILTER(AB$2:AB3, C$2:C3=C3), -3))} -> 0.76 | AD3: {=AVERAGE(_xlfn.TAKE(_xlfn._xlws.FILTER(AB$2:AB3, $C$2:$C3=$C3), -7))} -> 0.76 | AE3: {=_xlfn.IFS(OR(AC3=0, AD3=0), 0, (AC3-AD3)/AD3 > 0.03, 1, (AC3-AD3)/AD3 < -0.03, -1, TRUE, 0)} -> 0 | AF3: {=AVERAGE(_xlfn.TAKE(_xlfn._xlws.FILTER($Q$2:$Q3, $C$2:$C3=$C3), -3))} -> 97.3 | AG3: {=AVERAGE(_xlfn.TAKE(_xlfn._xlws.FILTER($Q$2:$Q3, $C$2:$C3=$C3), -7))} -> 97.3 | AH3: {=_xlfn.IFS(OR(AF3=0, AG3=0), 0, (AF3-AG3) > 1, 1, (AF3-AG3) < -1, -1, TRUE, 0)} -> 0 | AI3: {=MAX(_xlfn.TAKE(_xlfn._xlws.FILTER($Q$2:$Q3, $C$2:$C3=$C3), -10))} -> 97.3 | AJ3: =IF(X3=0,0,AB3/X3) -> 1.1692308 | AK3: {=_xlfn.IFS( OR(Q3=0,X3=0,AB3=0),"", AND(Q3>90,W3<=0,OR((X3/Z3)>1.25,(Y3/Z3)>1.1,(AC3/AD3)>1.1)),1, AND(Q3>60,AJ3>2,AE3<0),2, AND(Q3<60,AA3<0,AE3>0,W3<0),3, AND(Q3>40,(Y3/Z3)>1.25,AA3<=0),4, AND(Q3>25,AA3<0,AE3<0,W3<0),5, AND(Q3<50,AA3<0,AE3<=0,W3<=0),6, AND(Q3<10,R3<=10,AH3<=0,S3<0.03),7, AND(Q3>60,AI3>=80,(AI3-Q3)>10,W3>0,AE3<0),8, AND(Q3<25,AA3>0,AE3>0,W3>0,AH3>0),9, AND(Q3<60,W3>0,AA3>=0,AE3>=0,T3>U3,T3>V3),10, TRUE,"" )} | AL3: {=_xlfn.IFS( OR(Q3=0,X3=0,AB3=0),"", Q3 > 90, "IVPXtrm", X3 / Z3 > 1.25, "HV1Spke", Y3 / Z3 > 1.25, "HV3Spke", AB3 / AD3 > 1.25, "IV1Spke", AC3 / AD3 > 1.25, "IV3Spke", AJ3 > 2, "HiIV2HV", AND(S3 < 0.03, X3 / Z3 > 1.25), "IVExpn", TRUE,"" )} -> IVPXtrm | AM3: 46141 | AN3: 1630 | AO3: ZS | AP3: 134.73 | AQ3: -1.34 | AR3: -0.0098 | AS3: 135.12 | AT3: 135.715 | AU3: 131.74 | AV3: 46.06 | AW3: 0.65 | AX3: 0.76 | AY3: 162.94 | AZ3: 114.63 | BA3: 120.88 | BB3: 148.55 | BC3: 3211.06 | BD3: 14472.07 | BE3: 7.13 | BF3: 97.3 | BG3: 86.3 | BH3: -0.1 | BI3: 0

Sheet TW
A1: DateSymbol | B1: DateTime | C1: Sym | D1: DateSymbolTime | E1: Date1 | F1: Sequence | G1: FCF | H1: 20 DMA | I1: 50 DMA | J1: 200 DMA | K1: W_Vlm | L1: Avg Vlm (10day) | M1: Avg Vlm (3m) | N1: VlmRateOfChange | O1: W_Vlm_Expn_Ratio | P1: W_Prior-DayVlmExpnRatio | Q1: %Change | R1: Last Price | S1: W_Price_WkAgo | T1: W_%Change_Wk | U1: W_Vlm_RuleDesc | V1: A_MACD_BRR | W1: A_MACDH_D_BRR | X1: EarningsDays | Y1: Export Date | Z1: Export Time | AA1: Symbol | AB1: Last | AC1: %Change | AD1: Sector | AE1: Beta | AF1: StandardDeviation | AG1: Free Cash Flow Per Share - Current (Annual) | AH1: 52High | AI1: 52Low | AJ1: SimpleMovingAvg | AK1: SimpleMovingAvg | AL1: SimpleMovingAvg | AM1: A_MACDays_Streak | AN1: A_MACD_BRR1 | AO1: A_MACDH_D_BRR1 | AP1: Volume | AQ1: A_VolumeSpike | AR1: VolumeAvg | AS1: VolumeAvg | AT1: VolumeRateOfChange | AU1: A_Perf2M | AV1: A_Perf2Wk | AW1: A_Perf3D | AX1: A_3mnHigh | AY1: A_3mnLow | AZ1: A_3mnHighLow | BA1: A_3wkHighLow | BB1: A_EarningsDays | BC1: Market Cap
A2: =IF(AA2="","",E2&AA2) -> 46141ZM | B2: =E2 + TIME(LEFT(TEXT(F2,"0000"),2),RIGHT(TEXT(F2,"0000"),2),0) -> 46141.688 | C2: =IF(ISNUMBER(SEARCH("[",AA2)),LEFT(AA2,FIND("[",AA2)-1),AA2) -> ZM | D2: =IF(AA2="","",B2&C2) -> 46141.6875ZM | E2: =Y2 -> 46141 | F2: =Z2 -> 1630 | G2: =IF(AA2="","",IF(AG2="<empty>","",AG2)) -> 6.4 | H2: =IF(Z2="","",IF(AJ2="NaN",0,AJ2)) -> 86.92 | I2: =IF(AA2="","",IF(AK2="NaN",0,AK2)) -> 82.11 | J2: =IF(AA2="","",IF(AL2="NaN",0,AL2)) -> 82.69 | K2: =IF(AA2="","",IF(AP2="<empty>",0,AP2)) -> 6815835 | L2: =IF(AA2="","",IF(AR2="NaN",0,AR2)) -> 4431087.3 | M2: =IF(AA2="","",IF(AS2="NaN",0,AS2)) -> 4379189.9 | N2: =IF(AA2="","",IF(AT2="NaN",0,AT2)) -> 38.55 | O2: =IFERROR(K2/L2,0) -> 1.5381857 | P2: {=_xlfn.IFNA(_xlfn.XLOOKUP(C2, C$1:C1, O$1:O1, "", 0, -1), "")} | Q2: =AC2 -> 0.0507 | R2: =IF(E2<Dash!$AQ$5, C2, "") | S2: {=_xlfn.XLOOKUP(C2, R$1:R1, AB$1:AB1, 0, 0, -1)} -> 0 | T2: =IF(OR(AB2=0,S2=0),0,(AB2-S2)*100/S2) -> 0 | U2: {=_xlfn.IFS( AND(T2>12,O2>=2.8,N2>=120),1, AND(O2>=1.5,ABS(Q2)<0.003),2, AND(N2>=60,K2<L2,L2<=M2),3, AND(O2>=2.8,N2>=150),4, AND(L2<=1.05*M2,O2<1),5, AND(N2>=40,K2<L2,L2<=M2),6, AND(O2>=2,L2>M2,N2>=80,N2<150),7, AND(L2<=1.05*M2,O2>=2,N2>=60,Q2>0),8, AND(L2>M2,O2<1,P2>=1.5,N2>=30,Q2>0),9, AND(O2>=1.5,L2>M2,N2>=40,N2<140,Q2>0),10, TRUE,"" )} | V2: =IF(AA2="","",IF(AN2="NaN",0,AN2)) -> 1 | W2: =IF(AA2="","",IF(AO2="NaN",0,AO2)) -> 0.81 | X2: =IF(BB2="NaN",-99,BB2) -> 16 | Y2: 46141 | Z2: 1630 | AA2: ZM | AB2: 95.76 | AC2: 0.0507 | AD2: Information Technology | AE2: 1.5 | AF2: 4.32 | AG2: 6.4 | AH2: 97.58 | AI2: 69.15 | AJ2: 86.92 | AK2: 82.11 | AL2: 82.69 | AM2: 1 | AN2: 1 | AO2: 0.81 | AP2: 6815835 | AQ2: -200443.44 | AR2: 4431087.3 | AS2: 4379189.9 | AT2: 38.55 | AU2: 29.51 | AV2: 7.56 | AW2: 4.05 | AX2: 97.54 | AY2: 71.4 | AZ2: -71.4 | BA2: -77.13 | BB2: 16 | BC2: 28,217 M
A3: =IF(AA3="","",E3&AA3) -> 46141ZS | B3: =E3 + TIME(LEFT(TEXT(F3,"0000"),2),RIGHT(TEXT(F3,"0000"),2),0) -> 46141.688 | C3: =IF(ISNUMBER(SEARCH("[",AA3)),LEFT(AA3,FIND("[",AA3)-1),AA3) -> ZS | D3: =IF(AA3="","",B3&C3) -> 46141.6875ZS | E3: =Y3 -> 46141 | F3: =Z3 -> 1630 | G3: =IF(AA3="","",IF(AG3="<empty>","",AG3)) -> 5.55 | H3: =IF(Z3="","",IF(AJ3="NaN",0,AJ3)) -> 133.54 | I3: =IF(AA3="","",IF(AK3="NaN",0,AK3)) -> 145.07 | J3: =IF(AA3="","",IF(AL3="NaN",0,AL3)) -> 235.24 | K3: =IF(AA3="","",IF(AP3="<empty>",0,AP3)) -> 1339176 | L3: =IF(AA3="","",IF(AR3="NaN",0,AR3)) -> 3140769.1 | M3: =IF(AA3="","",IF(AS3="NaN",0,AS3)) -> 3008291.2 | N3: =IF(AA3="","",IF(AT3="NaN",0,AT3)) -> -81.76 | O3: =IFERROR(K3/L3,0) -> 0.42638474 | P3: {=_xlfn.IFNA(_xlfn.XLOOKUP(C3, C$1:C2, O$1:O2, "", 0, -1), "")} | Q3: =AC3 -> -0.0098 | R3: =IF(E3<Dash!$AQ$5, C3, "") | S3: {=_xlfn.XLOOKUP(C3, R$1:R2, AB$1:AB2, 0, 0, -1)} -> 0 | T3: =IF(OR(AB3=0,S3=0),0,(AB3-S3)*100/S3) -> 0 | U3: {=_xlfn.IFS( AND(T3>12,O3>=2.8,N3>=120),1, AND(O3>=1.5,ABS(Q3)<0.003),2, AND(N3>=60,K3<L3,L3<=M3),3, AND(O3>=2.8,N3>=150),4, AND(L3<=1.05*M3,O3<1),5, AND(N3>=40,K3<L3,L3<=M3),6, AND(O3>=2,L3>M3,N3>=80,N3<150),7, AND(L3<=1.05*M3,O3>=2,N3>=60,Q3>0),8, AND(L3>M3,O3<1,P3>=1.5,N3>=30,Q3>0),9, AND(O3>=1.5,L3>M3,N3>=40,N3<140,Q3>0),10, TRUE,"" )} -> 5 | V3: =IF(AA3="","",IF(AN3="NaN",0,AN3)) -> 0.58 | W3: =IF(AA3="","",IF(AO3="NaN",0,AO3)) -> -0.88 | X3: =IF(BB3="NaN",-99,BB3) -> 20 | Y3: 46141 | Z3: 1630 | AA3: ZS | AB3: 134.73 | AC3: -0.0098 | AD3: Information Technology | AE3: 1 | AF3: 6.56 | AG3: 5.55 | AH3: 336.99 | AI3: 114.625 | AJ3: 133.54 | AK3: 145.07 | AL3: 235.24 | AM3: -5 | AN3: 0.58 | AO3: -0.88 | AP3: 1339176 | AQ3: -100866.15 | AR3: 3140769.1 | AS3: 3008291.2 | AT3: -81.76 | AU3: -8.34 | AV3: 2.84 | AW3: -0.57 | AX3: 211.62 | AY3: 115.13 | AZ3: -115.13 | BA3: -115.13 | BB3: 20 | BC3: 21,663 M

Sheet TO
A1: DateSymbol | B1: DateTime | C1: Sym | D1: DateSymbolTime | E1: Date | F1: Sequence | G1: Market Cap | H1: Export Date | I1: Export Time | J1: Symbol | K1: Beta | L1: Market Cap | M1: Long-term Debt to Capital - Current (LTM) | N1: Price / Earnings Ratio - Current | O1: Price / Book Value Ratio - Current | P1: Return on Equity (ROE) - Current (LTM) | Q1: EPS | R1: Div. Yield - Current | S1: Sector | T1: Free Cash Flow Per Share - Current (LTM)
A2: =IF(J2="","",E2&J2) -> 46139ZM | B2: =E2 + TIME(LEFT(TEXT(F2,"0000"),2),RIGHT(TEXT(F2,"0000"),2),0) -> 46139.688 | C2: =IF(ISNUMBER(SEARCH("[",J2)),LEFT(J2,FIND("[",J2)-1),J2) -> ZM | D2: =IF(J2="","",B2&C2) -> 46139.6875ZM | E2: =H2 -> 46139 | F2: =I2 -> 1630 | G2: =VALUE(SUBSTITUTE(SUBSTITUTE(L2," M",""),",",""))*1000000 -> 26765000000 | H2: 46139 | I2: 1630 | J2: ZM | K2: 1.5 | L2: 26,765 M | M2: 0.3112 | N2: 14.896 | O2: 2.775 | P2: 20.275 | Q2: 6.18 | R2: <empty> | S2: Information Technology | T2: 6.4
A3: =IF(J3="","",E3&J3) -> 46139ZS | B3: =E3 + TIME(LEFT(TEXT(F3,"0000"),2),RIGHT(TEXT(F3,"0000"),2),0) -> 46139.688 | C3: =IF(ISNUMBER(SEARCH("[",J3)),LEFT(J3,FIND("[",J3)-1),J3) -> ZS | D3: =IF(J3="","",B3&C3) -> 46139.6875ZS | E3: =H3 -> 46139 | F3: =I3 -> 1630 | G3: =VALUE(SUBSTITUTE(SUBSTITUTE(L3," M",""),",",""))*1000000 -> 21564000000 | H3: 46139 | I3: 1630 | J3: ZS | K3: 1 | L3: 21,564 M | M3: 44.241 | N3: -465.55 | O3: 14.625 | P3: -3.5563 | Q3: -0.43 | R3: <empty> | S3: Information Technology | T3: 5.55

Sheet RR
A1: Key | B1: Y Ticker | C1: TOS Ticker | D1: Date | E1: Is Latest | F1: Latest Symbol | G1: Last Price | H1: Buy Trade | I1: Sell Trade | J1: Weight | K1: Prev Dt (<7 days) | L1: Prev Wt | M1: Modifier | N1: Entry | O1: Entry Wt | P1: Cont | Q1: Cont Wt | R1: Reverse | S1: BRR | T1: M TOS | U1: Ticker | V1: Name | W1: Outlook | X1: Sell Trade | Y1: Buy Trade | Z1: Last Price | AA1: Market Close | AB1: =_xlfn.MAXIFS(D:D,D:D,"<=" & Dash!AB9,D:D,">=" & Dash!AB10) -> 46141 | AC1: Look in RRT tab for mapping
A2: =D2&B2 -> 46141URA | B2: =_xlfn.XLOOKUP(U2,RRT!A:A,RRT!B:B) -> URA | C2: =_xlfn.XLOOKUP(U2,RRT!A:A,RRT!C:C) -> URA | D2: =AA2 -> 46141 | E2: =IF($AB$1=D2,"Y","") -> Y | F2: =IF(D2=_xlfn.MAXIFS(D:D,C:C,C2),C2,"") -> URA | G2: =Z2 -> 0 | H2: =X2 -> 0 | I2: =Y2 -> 0 | J2: =_xlfn.XLOOKUP(W2,Parm!$BH:$BH,Parm!$BI:$BI) -> 3 | K2: =IF(E2="","",IFERROR(_xlfn.MAXIFS(D$1:D1, B$1:B1, B2, D$1:D1, "<"&D2, D$1:D1, ">"&(D2-7),J$1:J1,"<>"&J2), "")) -> 0 | L2: =IF(OR(K2="",K2=0),"",_xlfn.XLOOKUP(K2&B2,A:A,J:J)) | M2: {=_xlfn.IFS(L2="","",J2<>L2,J2,TRUE,"")} | N2: {=IF(F2="","",_xlfn.IFS(AND(J2<=0,M2<0),"SellAll",J2<=-2,"SellAll",J2=-1,"SellWatch",J2=0,"Neutral",AND(J2>1,OR(M2>1,L2=0)),"BuySome",J2=3,"BuySome",J2=2,"BuySome",J2=1,"BuyWatch",TRUE,"Neutral"))} -> BuySome | O2: =_xlfn.XLOOKUP(N2,Parm!$AN$2:$AN$25,Parm!$AO$2:$AO$25,"") -> 9 | P2: {=IF(OR(F2="",M2=""),"",_xlfn.IFS(AND(_xlfn.NUMBERVALUE(J2)<=0,_xlfn.NUMBERVALUE(M2)<=0),"SellAll",AND(_xlfn.NUMBERVALUE(J2)>0,_xlfn.NUMBERVALUE(M2)<=0),"SellSome",AND(_xlfn.NUMBERVALUE(J2)>0,_xlfn.NUMBERVALUE(M2)>1),"BuyMore",AND(_xlfn.NUMBERVALUE(J2)>0,_xlfn.NUMBERVALUE(M2)>0),"BuySome",TRUE,""))} | Q2: =_xlfn.XLOOKUP(P2,Parm!$AN$2:$AN$25,Parm!$AO$2:$AO$25,"") | R2: =_xlfn.XLOOKUP(U2,RRT!A:A,RRT!D:D) -> N | S2: =IF(H2=0,"",IF(R2="Y",(G2-I2)/(H2-I2),(G2-H2)/(I2-H2))) | T2: {=IF(ISNA(_xlfn.XLOOKUP(C2,MA!B:B,,MA!B:B)),C2,"")} | U2: URA | V2: Global X Uranium ETF | W2: Bullish | X2: 0 | Y2: 0 | Z2: 0 | AA2: 46141
A3: =D3&B3 -> 46141XLY | B3: =_xlfn.XLOOKUP(U3,RRT!A:A,RRT!B:B) -> XLY | C3: =_xlfn.XLOOKUP(U3,RRT!A:A,RRT!C:C) -> XLY | D3: =AA3 -> 46141 | E3: =IF($AB$1=D3,"Y","") -> Y | F3: =IF(D3=_xlfn.MAXIFS(D:D,C:C,C3),C3,"") -> XLY | G3: =Z3 -> 0 | H3: =X3 -> 0 | I3: =Y3 -> 0 | J3: =_xlfn.XLOOKUP(W3,Parm!$BH:$BH,Parm!$BI:$BI) -> 3 | K3: =IF(E3="","",IFERROR(_xlfn.MAXIFS(D$1:D2, B$1:B2, B3, D$1:D2, "<"&D3, D$1:D2, ">"&(D3-7),J$1:J2,"<>"&J3), "")) -> 0 | L3: =IF(OR(K3="",K3=0),"",_xlfn.XLOOKUP(K3&B3,A:A,J:J)) | M3: {=_xlfn.IFS(L3="","",J3<>L3,J3,TRUE,"")} | N3: {=IF(F3="","",_xlfn.IFS(AND(J3<=0,M3<0),"SellAll",J3<=-2,"SellAll",J3=-1,"SellWatch",J3=0,"Neutral",AND(J3>1,OR(M3>1,L3=0)),"BuySome",J3=3,"BuySome",J3=2,"BuySome",J3=1,"BuyWatch",TRUE,"Neutral"))} -> BuySome | O3: =_xlfn.XLOOKUP(N3,Parm!$AN$2:$AN$25,Parm!$AO$2:$AO$25,"") -> 9 | P3: {=IF(OR(F3="",M3=""),"",_xlfn.IFS(AND(_xlfn.NUMBERVALUE(J3)<=0,_xlfn.NUMBERVALUE(M3)<=0),"SellAll",AND(_xlfn.NUMBERVALUE(J3)>0,_xlfn.NUMBERVALUE(M3)<=0),"SellSome",AND(_xlfn.NUMBERVALUE(J3)>0,_xlfn.NUMBERVALUE(M3)>1),"BuyMore",AND(_xlfn.NUMBERVALUE(J3)>0,_xlfn.NUMBERVALUE(M3)>0),"BuySome",TRUE,""))} | Q3: =_xlfn.XLOOKUP(P3,Parm!$AN$2:$AN$25,Parm!$AO$2:$AO$25,"") | R3: =_xlfn.XLOOKUP(U3,RRT!A:A,RRT!D:D) -> N | S3: =IF(H3=0,"",IF(R3="Y",(G3-I3)/(H3-I3),(G3-H3)/(I3-H3))) | T3: {=IF(ISNA(_xlfn.XLOOKUP(C3,MA!B:B,,MA!B:B)),C3,"")} | U3: XLY | V3: Consumer Discretionary Select Sector SPDR Fund | W3: Bullish | X3: 0 | Y3: 0 | Z3: 0 | AA3: 46141

Sheet call
A1: Key | B1: Symbol | C1: Date | D1: Outlook | E1: Outlook Modifier | F1: Prev Date | G1: Prev State | H1: Lastest Symbol | I1: Weight | J1: Modifier | K1: CAll Entry | L1: CAll Entry Wt | M1: CAll Cont | N1: CAll Cont Wt | O1: Miss | P1: TOS Lookup | Q1: MA Lookup | R1: Y Lookup | S1: Imported Date | T1: Symbol | U1: Outlook | V1: Outlook Modifier | Y1: =TODAY()-45 -> 46102
A2: =C2&B2 -> 46141META | B2: =T2 -> META | C2: =S2 -> 46141 | D2: =U2 -> BULLISH | E2: =V2 -> long | F2: =IFERROR(_xlfn.MAXIFS(C:C, B:B, B2, C:C, "<"&C2), "") -> 0 | G2: =IF(F2>0,_xlfn.XLOOKUP(F2&B2,A:A,I:I),"") | H2: =IF(C2<$Y$1,"",IF(C2=_xlfn.MAXIFS(C:C,B:B,B2),B2,"")) -> META | I2: =_xlfn.XLOOKUP(E2,Parm!$BE:$BE,Parm!$BF:$BF) -> 3 | J2: =IF(G2<>"",I2-G2,0) -> 0 | K2: {=IF(H2="","",_xlfn.IFS(AND(I2<=0,J2<0),"SellAll",I2<=-2,"SellAll",I2=-1,"SellWatch",C2<Dash!$AH$3,"Neutral",I2=0,"Neutral",AND(I2>1,OR(J2>1,G2=0)),"BuySome",I2=3,"BuySome",I2=2,"BuySome",I2=1,"BuyWatch",TRUE,"Neutral"))} -> BuySome | L2: =_xlfn.XLOOKUP(K2,Parm!$AN$2:$AN$25,Parm!$AO$2:$AO$25,"") -> 9 | M2: {=IF(H2="","",_xlfn.IFS(AND(I2<=0,J2<0),"SellAll",AND(I2>0,J2<0),"SellSome",C2<Dash!$AH$3,"",AND(I2>0,J2>1),"BuyMore",AND(I2>0,J2>0),"BuySome",TRUE,""))} | N2: =_xlfn.XLOOKUP(M2,Parm!$AN$2:$AN$25,Parm!$AO$2:$AO$25,"") | O2: {=_xlfn.IFS(I2<=0,"",LEFT(B2,1)="$","",AND(ISNA(Q2),C2>$Y$1),B2,TRUE,"")} -> META | P2: =_xlfn.XLOOKUP(B2,TL!C:C,TL!C:C) -> #N/A | Q2: =_xlfn.XLOOKUP(B2,MA!B:B,MA!B:B) -> #N/A | R2: =_xlfn.XLOOKUP(B2,Y!C:C,Y!C:C) -> #N/A | S2: 46141 | T2: META | U2: BULLISH | V2: long
A3: =C3&B3 -> 46141ODFL | B3: =T3 -> ODFL | C3: =S3 -> 46141 | D3: =U3 -> BEARISH | E3: =V3 -> short | F3: =IFERROR(_xlfn.MAXIFS(C:C, B:B, B3, C:C, "<"&C3), "") -> 0 | G3: =IF(F3>0,_xlfn.XLOOKUP(F3&B3,A:A,I:I),"") | H3: =IF(C3<$Y$1,"",IF(C3=_xlfn.MAXIFS(C:C,B:B,B3),B3,"")) -> ODFL | I3: =_xlfn.XLOOKUP(E3,Parm!$BE:$BE,Parm!$BF:$BF) -> -3 | J3: =IF(G3<>"",I3-G3,0) -> 0 | K3: {=IF(H3="","",_xlfn.IFS(AND(I3<=0,J3<0),"SellAll",I3<=-2,"SellAll",I3=-1,"SellWatch",C3<Dash!$AH$3,"Neutral",I3=0,"Neutral",AND(I3>1,OR(J3>1,G3=0)),"BuySome",I3=3,"BuySome",I3=2,"BuySome",I3=1,"BuyWatch",TRUE,"Neutral"))} -> SellAll | L3: =_xlfn.XLOOKUP(K3,Parm!$AN$2:$AN$25,Parm!$AO$2:$AO$25,"") -> -10 | M3: {=IF(H3="","",_xlfn.IFS(AND(I3<=0,J3<0),"SellAll",AND(I3>0,J3<0),"SellSome",C3<Dash!$AH$3,"",AND(I3>0,J3>1),"BuyMore",AND(I3>0,J3>0),"BuySome",TRUE,""))} | N3: =_xlfn.XLOOKUP(M3,Parm!$AN$2:$AN$25,Parm!$AO$2:$AO$25,"") | O3: {=_xlfn.IFS(I3<=0,"",LEFT(B3,1)="$","",AND(ISNA(Q3),C3>$Y$1),B3,TRUE,"")} | P3: =_xlfn.XLOOKUP(B3,TL!C:C,TL!C:C) -> #N/A | Q3: =_xlfn.XLOOKUP(B3,MA!B:B,MA!B:B) -> #N/A | R3: =_xlfn.XLOOKUP(B3,Y!C:C,Y!C:C) -> #N/A | S3: 46141 | T3: ODFL | U3: BEARISH | V3: short
A4: =C4&B4 -> 46141HUM | B4: =T4 -> HUM | C4: =S4 -> 46141 | D4: =U4 -> NEUTRAL | E4: =V4 -> neutral | F4: =IFERROR(_xlfn.MAXIFS(C:C, B:B, B4, C:C, "<"&C4), "") -> 0 | G4: =IF(F4>0,_xlfn.XLOOKUP(F4&B4,A:A,I:I),"") | H4: =IF(C4<$Y$1,"",IF(C4=_xlfn.MAXIFS(C:C,B:B,B4),B4,"")) -> HUM | I4: =_xlfn.XLOOKUP(E4,Parm!$BE:$BE,Parm!$BF:$BF) -> 0 | J4: =IF(G4<>"",I4-G4,0) -> 0 | K4: {=IF(H4="","",_xlfn.IFS(AND(I4<=0,J4<0),"SellAll",I4<=-2,"SellAll",I4=-1,"SellWatch",C4<Dash!$AH$3,"Neutral",I4=0,"Neutral",AND(I4>1,OR(J4>1,G4=0)),"BuySome",I4=3,"BuySome",I4=2,"BuySome",I4=1,"BuyWatch",TRUE,"Neutral"))} -> Neutral | L4: =_xlfn.XLOOKUP(K4,Parm!$AN$2:$AN$25,Parm!$AO$2:$AO$25,"") -> 0 | M4: {=IF(H4="","",_xlfn.IFS(AND(I4<=0,J4<0),"SellAll",AND(I4>0,J4<0),"SellSome",C4<Dash!$AH$3,"",AND(I4>0,J4>1),"BuyMore",AND(I4>0,J4>0),"BuySome",TRUE,""))} | N4: =_xlfn.XLOOKUP(M4,Parm!$AN$2:$AN$25,Parm!$AO$2:$AO$25,"") | O4: {=_xlfn.IFS(I4<=0,"",LEFT(B4,1)="$","",AND(ISNA(Q4),C4>$Y$1),B4,TRUE,"")} | P4: =_xlfn.XLOOKUP(B4,TL!C:C,TL!C:C) -> #N/A | Q4: =_xlfn.XLOOKUP(B4,MA!B:B,MA!B:B) -> #N/A | R4: =_xlfn.XLOOKUP(B4,Y!C:C,Y!C:C) -> #N/A | S4: 46141 | T4: HUM | U4: NEUTRAL | V4: neutral

Sheet F
A1: Key | B1: Symbol | C1: Ignore | D1: Date | E1: Price Paid | F1: Qty | G1: Cur Val | H1: Prev Qty | I1: Prev Val | J1: New leg | K1: Leg ID | L1: Qty Diff | M1: Snapshot P/L | N1: Running P/L | O1: Leg Status | P1: Leg P/L | Q1: Final Status | R1: Final P/L | S1: M TOS | T1: Y Lookup | U1: TOS Lookup | V1: MA Lookup | W1: Export Date | X1: Account Number | Y1: Account Name | Z1: Symbol | AA1: Description | AB1: Quantity | AC1: Last Price | AD1: Last Price Change | AE1: Current Value | AF1: Today's Gain/Loss Dollar | AG1: Today's Gain/Loss Percent | AH1: Total Gain/Loss Dollar | AI1: Total Gain/Loss Percent | AJ1: Percent Of Account | AK1: Cost Basis Total | AL1: Average Cost Basis | AM1: Type | AO1: Today | AP1: =Dash!$AB$2 -> 46142 | AQ1: =_xlfn.MAXIFS(D:D,D:D,"<=" & AP1) -> 46126
A2: =D2&Z2 -> 46126DOW | B2: =Z2 -> DOW | C2: =IF(B2="SPAXX**","Y","") | D2: =W2 -> 46126 | E2: =AC2 -> 39.16 | F2: =AB2 -> 150 | G2: =AE2 -> 5874 | H2: {=_xlfn.XLOOKUP(1, (B$1:B1=B2)*(K$1:K1=K2), F$1:F1, 0, 0, -1)} -> 0 | I2: {=_xlfn.XLOOKUP(1, (B$1:B1=B2)*(K$1:K1=K2), G$1:G1, 0, 0, -1)} -> 0 | J2: =IF(COUNTIFS(B$1:B1, B2, D$1:D1, _xlfn.MAXIFS(D$1:D1,D$1:D1,"<"&D2))>0, 0, 1) -> 1 | K2: {=IF(J2=1, _xlfn.MAXIFS(K$1:K1,B$1:B1,B2)+1, _xlfn.XLOOKUP(B2, B$1:B1, K$1:K1, 0, 0, -1))} -> 1 | L2: =IF(I2="","",F2-H2) -> 150 | M2: =IF(OR(H2=0, K2=""), 0, G2 - (I2/H2 * F2)) -> 0 | N2: =SUMIFS(M$1:M2, B$1:B2, B2, K$1:K2, K2) -> 0 | O2: =IF(COUNTIFS(B:B, B2, D:D, _xlfn.MINIFS(D:D, D:D, ">"&D2))=0, IF(D2=MAX(D:D),"","Closed"), "") | P2: =IF(OR(F2=0, O2="Closed"), N2, "") | Q2: =IF(COUNTIFS(B3:B$94716, B2)=0, "Final", "") -> Final | R2: =IF(Q2="Final", SUMIFS(M$1:M2, B$1:B2, B2), "") -> 0 | S2: =IF(AND(ISNA(V2),O2="Final"),B2,"") | T2: =IF(C2="Y","",_xlfn.XLOOKUP(Z2,Y!C:C,Y!C:C)) -> #N/A | U2: =IF(C2="Y","",_xlfn.XLOOKUP(Z2,TL!C:C,TL!C:C)) -> #N/A | V2: =IF(C2="Y","",_xlfn.XLOOKUP(Z2,MA!B:B,MA!B:B)) -> #N/A | W2: 46126 | X2: 249118149 | Y2: Rollover IRA | Z2: DOW | AA2: DOW INC COM | AB2: 150 | AC2: 39.16 | AD2: -0.95 | AE2: 5874 | AF2: -142.5 | AG2: -0.0237 | AH2: 52.01 | AI2: 0.0089 | AJ2: 0.0341 | AK2: 5821.99 | AL2: 38.81 | AM2: Cash

Sheet CS
A1: Key | B1: Symbol | C1: Ignore | D1: Date | E1: Price Paid | F1: Qty | G1: Cost | H1: Prev Qty | I1: Prev Val | J1: New leg | K1: Leg ID | L1: Qty Diff | M1: Snapshot P/L | N1: Running P/L | O1: Leg Status | P1: Leg P/L | Q1: Final Status | R1: Final P/L | S1: Account | T1: M TOS | U1: Y Lookup | V1: TOS Lookup | W1: MA Lookup | X1: Account | Y1: Imported Date | Z1: Symbol | AA1: Description | AB1: Qty (Quantity) | AC1: Price | AD1: Price Chng $ (Price Change $) | AE1: Price Chng % (Price Change %) | AF1: Mkt Val (Market Value) | AG1: Day Chng $ (Day Change $) | AH1: Day Chng % (Day Change %) | AI1: Cost Basis | AJ1: Gain $ (Gain/Loss $) | AK1: Gain % (Gain/Loss %) | AL1: Reinvest? | AM1: Reinvest Capital Gains? | AN1: Security Type
A2: =D2&B2 -> 46141XTL | B2: =Z2 -> XTL | C2: =IF(OR(B2="--",B2="Cash & Cash Investments",B2="SWPPX",B2="Account Total"),"Y","") | D2: =Y2 -> 46141 | E2: =IF(U2="",0,AI2/AB2) -> #N/A | F2: =IF(AB2="--",0,AB2) -> 75 | G2: =AI2 -> 15868.13 | H2: {=_xlfn.XLOOKUP(1, (B$1:B1=B2)*(K$1:K1=K2), F$1:F1, 0, 0, -1)} -> 0 | I2: {=_xlfn.XLOOKUP(1, (B$1:B1=B2)*(K$1:K1=K2), G$1:G1, 0, 0, -1)} -> 0 | J2: =IF(COUNTIFS(B$1:B1, B2, D$1:D1, _xlfn.MAXIFS(D$1:D1,D$1:D1,"<"&D2))>0, 0, 1) -> 1 | K2: {=IF(J2=1, _xlfn.MAXIFS(K$1:K1,B$1:B1,B2)+1, _xlfn.XLOOKUP(B2, B$1:B1, K$1:K1, 0, 0, -1))} -> 1 | L2: =IF(I2="","",F2-H2) -> 75 | M2: =IF(OR(H2=0, K2=""), 0, G2 - (I2/H2 * F2)) -> 0 | N2: =SUMIFS(M$1:M2, B$1:B2, B2, K$1:K2, K2) -> 0 | O2: =IF(COUNTIFS(B:B, B2, D:D, _xlfn.MINIFS(D:D, D:D, ">"&D2))=0, IF(D2=MAX(D:D),"","Closed"), "") | P2: =IF(OR(F2=0, O2="Closed"), N2, "") | Q2: =IF(COUNTIFS(B3:B$92426, B2)=0, "Final", "") -> Final | R2: =IF(Q2="Final", SUMIFS(M$1:M2, B$1:B2, B2), "") -> 0 | S2: =X2 -> Rollover_IRA ...892 | T2: =IF(AND(Q2="Final",ISNA(W2)),B2,"") -> XTL | U2: =IF(C2="Y","",_xlfn.XLOOKUP(Z2,Y!C:C,Y!C:C)) -> #N/A | V2: =IF(C2="Y","",_xlfn.XLOOKUP(Z2,TL!C:C,TL!C:C)) -> #N/A | W2: =IF(C2="Y","",_xlfn.XLOOKUP(Z2,MA!B:B,MA!B:B)) -> #N/A | X2: Rollover_IRA ...892 | Y2: 46141 | Z2: XTL | AA2: STATE STREET SPDR S&P TELECOM ETF | AB2: 75 | AC2: 214.3 | AD2: 3.8 | AE2: 0.0181 | AF2: 16072.5 | AG2: 227.37 | AH2: 0.0143 | AI2: 15868.13 | AJ2: 204.37 | AK2: 0.0129 | AL2: No | AM2: N/A | AN2: ETFs & Closed End Funds

Sheet etf
A1: Key | B1: Symbol | C1: Date | D1: Outlook | E1: BRR | F1: TRR | G1: Weight | H1: Is Latest? | I1: Latest Symbol | J1: ETF Entry | K1: ETF Entry Wt | L1: ETF Cont | M1: ETF Cont Wt | N1: Date2 | O1: ETF Change | P1: Error | Q1: MA | R1: Imported Date | S1: Sector | T1: Ticker | U1: Date Added | V1: Recent Price | W1: BRR | X1: TRR | Y1: Asset Class | AA1: Include | AB1: =Dash!AH4 -> 46111
A2: 460190 | B2: 0 | C2: 46019 | D2: BULLISH | E2: 0 | F2: 0 | G2: 3 | N2: 46019 | R2: 46019 | S2: BULLISH
A3: 46019BUXX | B3: BUXX | C3: 46019 | D3: BULLISH | E3: 20.32 | F3: 20.41 | G3: 3 | N3: 46019 | R3: 46019 | S3: Income Short Maturity | T3: BUXX | U3: 45224 | V3: 20.36 | W3: 20.32 | X3: 20.41 | Y3: Domestic Fixed Income

Sheet etfchg
A1: Date | B1: Action | C1: Chg | D1: Wt | E1: Date2 | F1: Wt | G1: MA | H1: Imported Date | I1: Desc | J1: Symbol | K1: Outlook | L1: Change | N1: Keep the data only for a week
A2: =IF(H2="","",DATEVALUE(TEXT(H2,"mm/dd/yyyy"))) -> 45996 | B2: =IF(K2="Long",IF(L2="Long","BuySome","SellAll"),IF(L2="Short","SellAll","Neutral")) -> SellAll | C2: {=IF(ISNA(_xlfn.XLOOKUP(J2,#REF!,#REF!)),J2,"")} | D2: =_xlfn.IFNA(_xlfn.XLOOKUP(B2,Parm!$AN$2:$AN$25,Parm!$AO$2:$AO$25),"") -> -10 | E2: =H2 -> 45996 | F2: =IF(AND(K2="Long",L2="Neutral"),-3,_xlfn.XLOOKUP(L2,Parm!$BE$2:$BE$11,Parm!$BF$2:$BF$11)) -> -3 | G2: =IF(OR(J2="Dummy",F2<=0),"",IF(ISNA(_xlfn.XLOOKUP(C2,MA!B:B,MA!B:B)),C2,"")) | H2: 45996 | I2: Don’t Delete | J2: Dummy | K2: Long | L2: Neutral

Sheet II
A1: Key | B1: Symbol | C1: Date | D1: Outlook | E1: Weight | F1: Is Latest? | G1: Latest Symbol | H1: II Entry | I1: II Entry | J1: II Cont | K1: II Cont | L1: Date2 | M1: II Change | N1: M TOS | O1: Imported Date | P1: Outlook | Q1: Ticker | S1: Include | T1: =Dash!$AH$7 -> 46111
